2023-10-03 10:59:58,186 - ERROR - Internal Server Error: /sendotp
Traceback (most recent call last):
  File "C:\python311\Lib\site-packages\django\core\handlers\exception.py", line 55, in inner
    response = get_response(request)
               ^^^^^^^^^^^^^^^^^^^^^
  File "C:\python311\Lib\site-packages\django\core\handlers\base.py", line 197, in _get_response
    response = wrapped_callback(request, *callback_args, **callback_kwargs)
               ^^^^^^^^^^^^^^^^^^^^^^^^^^^^^^^^^^^^^^^^^^^^^^^^^^^^^^^^^^^^
  File "D:\Coding\Projects\designcrafter\designcrafter\designcrafter\views.py", line 42, in sendotp
    send_mail(subject, message, from_email, recipient_list)
  File "C:\python311\Lib\site-packages\django\core\mail\__init__.py", line 87, in send_mail
    return mail.send()
           ^^^^^^^^^^^
  File "C:\python311\Lib\site-packages\django\core\mail\message.py", line 298, in send
    return self.get_connection(fail_silently).send_messages([self])
           ^^^^^^^^^^^^^^^^^^^^^^^^^^^^^^^^^^^^^^^^^^^^^^^^^^^^^^^^
  File "C:\python311\Lib\site-packages\django\core\mail\backends\smtp.py", line 127, in send_messages
    new_conn_created = self.open()
                       ^^^^^^^^^^^
  File "C:\python311\Lib\site-packages\django\core\mail\backends\smtp.py", line 94, in open
    self.connection.login(self.username, self.password)
  File "C:\python311\Lib\smtplib.py", line 750, in login
    raise last_exception
  File "C:\python311\Lib\smtplib.py", line 739, in login
    (code, resp) = self.auth(
                   ^^^^^^^^^^
  File "C:\python311\Lib\smtplib.py", line 662, in auth
    raise SMTPAuthenticationError(code, resp)
smtplib.SMTPAuthenticationError: (535, b'5.7.8 Username and Password not accepted. Learn more at\n5.7.8  https://support.google.com/mail/?p=BadCredentials x10-20020a63b34a000000b0056946623d7esm402631pgt.55 - gsmtp')
2023-10-04 10:00:17,920 - WARNING - Not Found: /
2023-10-04 10:00:18,051 - WARNING - Not Found: /favicon.ico
2023-10-04 10:09:35,991 - INFO - D:\Coding\Projects\designcrafter\designcrafter\designcrafter\views.py changed, reloading.
2023-10-04 10:10:22,781 - INFO - D:\Coding\Projects\designcrafter\designcrafter\designcrafter\urls.py changed, reloading.
2023-10-04 10:10:32,496 - WARNING - Not Found: /
2023-10-04 10:17:17,466 - INFO - D:\Coding\Projects\designcrafter\designcrafter\designcrafter\views.py changed, reloading.
2023-10-04 10:32:49,571 - INFO - D:\Coding\Projects\designcrafter\designcrafter\designcrafter\views.py changed, reloading.
2023-10-04 10:32:55,789 - INFO - D:\Coding\Projects\designcrafter\designcrafter\designcrafter\views.py changed, reloading.
2023-10-04 10:33:31,662 - INFO - D:\Coding\Projects\designcrafter\designcrafter\designcrafter\views.py changed, reloading.
2023-10-04 10:34:22,991 - INFO - D:\Coding\Projects\designcrafter\designcrafter\designcrafter\models.py changed, reloading.
2023-10-04 10:41:38,799 - INFO - D:\Coding\Projects\designcrafter\designcrafter\designcrafter\views.py changed, reloading.
2023-10-04 10:43:52,209 - INFO - D:\Coding\Projects\designcrafter\designcrafter\designcrafter\views.py changed, reloading.
2023-10-04 10:44:13,709 - INFO - D:\Coding\Projects\designcrafter\designcrafter\designcrafter\views.py changed, reloading.
2023-10-04 10:44:40,304 - INFO - D:\Coding\Projects\designcrafter\designcrafter\designcrafter\views.py changed, reloading.
2023-10-04 10:46:09,508 - INFO - D:\Coding\Projects\designcrafter\designcrafter\designcrafter\views.py changed, reloading.
2023-10-04 10:46:13,542 - INFO - D:\Coding\Projects\designcrafter\designcrafter\designcrafter\views.py changed, reloading.
2023-10-04 10:51:37,260 - INFO - D:\Coding\Projects\designcrafter\designcrafter\designcrafter\views.py changed, reloading.
2023-10-04 10:52:01,932 - WARNING - Not Found: /action_page.php
2023-10-04 10:53:56,515 - WARNING - Not Found: /action_page.php
2023-10-04 10:53:59,933 - WARNING - Not Found: /action_page.php
2023-10-04 10:54:15,089 - WARNING - Not Found: /verify_otp
2023-10-04 10:55:21,847 - WARNING - Not Found: /verify_otp
2023-10-04 10:55:56,461 - INFO - D:\Coding\Projects\designcrafter\designcrafter\designcrafter\urls.py changed, reloading.
2023-10-04 10:55:59,285 - ERROR - Internal Server Error: /verify_otp
Traceback (most recent call last):
  File "C:\python311\Lib\site-packages\django\core\handlers\exception.py", line 55, in inner
    response = get_response(request)
               ^^^^^^^^^^^^^^^^^^^^^
  File "C:\python311\Lib\site-packages\django\core\handlers\base.py", line 197, in _get_response
    response = wrapped_callback(request, *callback_args, **callback_kwargs)
               ^^^^^^^^^^^^^^^^^^^^^^^^^^^^^^^^^^^^^^^^^^^^^^^^^^^^^^^^^^^^
  File "D:\Coding\Projects\designcrafter\designcrafter\designcrafter\views.py", line 64, in verify_otp
    if user.user_otp==ps:
       ^^^^^^^^^^^^^
AttributeError: 'str' object has no attribute 'user_otp'
2023-10-04 10:58:35,076 - INFO - D:\Coding\Projects\designcrafter\designcrafter\designcrafter\views.py changed, reloading.
2023-10-04 10:58:50,431 - INFO - D:\Coding\Projects\designcrafter\designcrafter\designcrafter\views.py changed, reloading.
2023-10-04 10:58:53,637 - ERROR - Internal Server Error: /verify_otp
Traceback (most recent call last):
  File "C:\python311\Lib\site-packages\django\core\handlers\exception.py", line 55, in inner
    response = get_response(request)
               ^^^^^^^^^^^^^^^^^^^^^
  File "C:\python311\Lib\site-packages\django\core\handlers\base.py", line 197, in _get_response
    response = wrapped_callback(request, *callback_args, **callback_kwargs)
               ^^^^^^^^^^^^^^^^^^^^^^^^^^^^^^^^^^^^^^^^^^^^^^^^^^^^^^^^^^^^
  File "D:\Coding\Projects\designcrafter\designcrafter\designcrafter\views.py", line 60, in verify_otp
    user = user.objects.get(email=us)
           ^^^^
UnboundLocalError: cannot access local variable 'user' where it is not associated with a value
2023-10-04 10:59:10,056 - INFO - D:\Coding\Projects\designcrafter\designcrafter\designcrafter\views.py changed, reloading.
2023-10-04 10:59:17,163 - INFO - D:\Coding\Projects\designcrafter\designcrafter\designcrafter\models.py changed, reloading.
2023-10-04 11:05:44,778 - INFO - D:\Coding\Projects\designcrafter\designcrafter\designcrafter\views.py changed, reloading.
2023-10-04 11:07:57,199 - INFO - D:\Coding\Projects\designcrafter\designcrafter\designcrafter\views.py changed, reloading.
2023-10-04 11:08:19,073 - ERROR - Internal Server Error: /verify_otp
Traceback (most recent call last):
  File "C:\python311\Lib\site-packages\django\core\handlers\exception.py", line 55, in inner
    response = get_response(request)
               ^^^^^^^^^^^^^^^^^^^^^
  File "C:\python311\Lib\site-packages\django\core\handlers\base.py", line 197, in _get_response
    response = wrapped_callback(request, *callback_args, **callback_kwargs)
               ^^^^^^^^^^^^^^^^^^^^^^^^^^^^^^^^^^^^^^^^^^^^^^^^^^^^^^^^^^^^
  File "D:\Coding\Projects\designcrafter\designcrafter\designcrafter\views.py", line 59, in verify_otp
    user = Newuser.objects.get(user_email=us)
           ^^^^^^^^^^^^^^^^^^^^^^^^^^^^^^^^^^
  File "C:\python311\Lib\site-packages\django\db\models\manager.py", line 87, in manager_method
    return getattr(self.get_queryset(), name)(*args, **kwargs)
           ^^^^^^^^^^^^^^^^^^^^^^^^^^^^^^^^^^^^^^^^^^^^^^^^^^^
  File "C:\python311\Lib\site-packages\django\db\models\query.py", line 640, in get
    raise self.model.MultipleObjectsReturned(
designcrafter.models.Newuser.MultipleObjectsReturned: get() returned more than one Newuser -- it returned 2!
2023-10-04 11:16:43,513 - INFO - D:\Coding\Projects\designcrafter\designcrafter\designcrafter\views.py changed, reloading.
2023-10-04 11:16:45,790 - ERROR - Internal Server Error: /verify_otp
Traceback (most recent call last):
  File "C:\python311\Lib\site-packages\django\core\handlers\exception.py", line 55, in inner
    response = get_response(request)
               ^^^^^^^^^^^^^^^^^^^^^
  File "C:\python311\Lib\site-packages\django\core\handlers\base.py", line 197, in _get_response
    response = wrapped_callback(request, *callback_args, **callback_kwargs)
               ^^^^^^^^^^^^^^^^^^^^^^^^^^^^^^^^^^^^^^^^^^^^^^^^^^^^^^^^^^^^
  File "D:\Coding\Projects\designcrafter\designcrafter\designcrafter\views.py", line 64, in verify_otp
    if user.user_otp==ps:
       ^^^^^^^^^^^^^
AttributeError: 'QuerySet' object has no attribute 'user_otp'
2023-10-04 11:19:12,687 - INFO - D:\Coding\Projects\designcrafter\designcrafter\designcrafter\views.py changed, reloading.
2023-10-04 11:23:23,836 - INFO - D:\Coding\Projects\designcrafter\designcrafter\designcrafter\views.py changed, reloading.
2023-10-04 11:24:47,964 - INFO - D:\Coding\Projects\designcrafter\designcrafter\designcrafter\views.py changed, reloading.
2023-10-04 11:24:52,424 - ERROR - Internal Server Error: /verify_otp
Traceback (most recent call last):
  File "C:\python311\Lib\site-packages\django\core\handlers\exception.py", line 55, in inner
    response = get_response(request)
               ^^^^^^^^^^^^^^^^^^^^^
  File "C:\python311\Lib\site-packages\django\core\handlers\base.py", line 197, in _get_response
    response = wrapped_callback(request, *callback_args, **callback_kwargs)
               ^^^^^^^^^^^^^^^^^^^^^^^^^^^^^^^^^^^^^^^^^^^^^^^^^^^^^^^^^^^^
  File "D:\Coding\Projects\designcrafter\designcrafter\designcrafter\views.py", line 64, in verify_otp
    if user.user_otp==ps:
       ^^^^^^^^^^^^^
AttributeError: 'QuerySet' object has no attribute 'user_otp'
2023-10-04 11:28:32,057 - INFO - D:\Coding\Projects\designcrafter\designcrafter\designcrafter\views.py changed, reloading.
2023-10-04 11:28:39,144 - INFO - D:\Coding\Projects\designcrafter\designcrafter\designcrafter\views.py changed, reloading.
2023-10-04 11:29:18,081 - INFO - D:\Coding\Projects\designcrafter\designcrafter\designcrafter\views.py changed, reloading.
2023-10-04 11:29:26,197 - INFO - D:\Coding\Projects\designcrafter\designcrafter\designcrafter\views.py changed, reloading.
2023-10-04 11:33:01,842 - INFO - D:\Coding\Projects\designcrafter\designcrafter\designcrafter\views.py changed, reloading.
2023-10-04 11:33:05,847 - ERROR - Internal Server Error: /verify_otp
Traceback (most recent call last):
  File "C:\python311\Lib\site-packages\django\core\handlers\exception.py", line 55, in inner
    response = get_response(request)
               ^^^^^^^^^^^^^^^^^^^^^
  File "C:\python311\Lib\site-packages\django\core\handlers\base.py", line 197, in _get_response
    response = wrapped_callback(request, *callback_args, **callback_kwargs)
               ^^^^^^^^^^^^^^^^^^^^^^^^^^^^^^^^^^^^^^^^^^^^^^^^^^^^^^^^^^^^
  File "D:\Coding\Projects\designcrafter\designcrafter\designcrafter\views.py", line 59, in verify_otp
    user = Newuser.objects.get(user_email=us)
           ^^^^^^^^^^^^^^^^^^^^^^^^^^^^^^^^^^
  File "C:\python311\Lib\site-packages\django\db\models\manager.py", line 87, in manager_method
    return getattr(self.get_queryset(), name)(*args, **kwargs)
           ^^^^^^^^^^^^^^^^^^^^^^^^^^^^^^^^^^^^^^^^^^^^^^^^^^^
  File "C:\python311\Lib\site-packages\django\db\models\query.py", line 640, in get
    raise self.model.MultipleObjectsReturned(
designcrafter.models.Newuser.MultipleObjectsReturned: get() returned more than one Newuser -- it returned 2!
2023-10-04 11:33:55,218 - ERROR - Internal Server Error: /verify_otp
Traceback (most recent call last):
  File "C:\python311\Lib\site-packages\django\core\handlers\exception.py", line 55, in inner
    response = get_response(request)
               ^^^^^^^^^^^^^^^^^^^^^
  File "C:\python311\Lib\site-packages\django\core\handlers\base.py", line 197, in _get_response
    response = wrapped_callback(request, *callback_args, **callback_kwargs)
               ^^^^^^^^^^^^^^^^^^^^^^^^^^^^^^^^^^^^^^^^^^^^^^^^^^^^^^^^^^^^
  File "D:\Coding\Projects\designcrafter\designcrafter\designcrafter\views.py", line 65, in verify_otp
    login(request, user)
TypeError: login() takes 1 positional argument but 2 were given
2023-10-05 09:16:47,686 - WARNING - Not Found: /
2023-10-05 09:16:47,914 - WARNING - Not Found: /favicon.ico
2023-10-05 09:18:07,213 - ERROR - Internal Server Error: /verify_otp
Traceback (most recent call last):
  File "C:\python311\Lib\site-packages\django\core\handlers\exception.py", line 55, in inner
    response = get_response(request)
               ^^^^^^^^^^^^^^^^^^^^^
  File "C:\python311\Lib\site-packages\django\core\handlers\base.py", line 197, in _get_response
    response = wrapped_callback(request, *callback_args, **callback_kwargs)
               ^^^^^^^^^^^^^^^^^^^^^^^^^^^^^^^^^^^^^^^^^^^^^^^^^^^^^^^^^^^^
  File "D:\Coding\Projects\designcrafter\designcrafter\designcrafter\views.py", line 65, in verify_otp
    login(request, user)
TypeError: login() takes 1 positional argument but 2 were given
2023-10-05 09:20:05,762 - INFO - D:\Coding\Projects\designcrafter\designcrafter\designcrafter\views.py changed, reloading.
2023-10-05 09:20:10,837 - ERROR - Internal Server Error: /verify_otp
Traceback (most recent call last):
  File "C:\python311\Lib\site-packages\django\core\handlers\exception.py", line 55, in inner
    response = get_response(request)
               ^^^^^^^^^^^^^^^^^^^^^
  File "C:\python311\Lib\site-packages\django\core\handlers\base.py", line 197, in _get_response
    response = wrapped_callback(request, *callback_args, **callback_kwargs)
               ^^^^^^^^^^^^^^^^^^^^^^^^^^^^^^^^^^^^^^^^^^^^^^^^^^^^^^^^^^^^
  File "D:\Coding\Projects\designcrafter\designcrafter\designcrafter\views.py", line 66, in verify_otp
    login(request, user)
TypeError: login() takes 1 positional argument but 2 were given
2023-10-05 09:21:38,448 - INFO - D:\Coding\Projects\designcrafter\designcrafter\designcrafter\views.py changed, reloading.
2023-10-05 09:21:44,356 - ERROR - Internal Server Error: /verify_otp
Traceback (most recent call last):
  File "C:\python311\Lib\site-packages\django\core\handlers\exception.py", line 55, in inner
    response = get_response(request)
               ^^^^^^^^^^^^^^^^^^^^^
  File "C:\python311\Lib\site-packages\django\core\handlers\base.py", line 197, in _get_response
    response = wrapped_callback(request, *callback_args, **callback_kwargs)
               ^^^^^^^^^^^^^^^^^^^^^^^^^^^^^^^^^^^^^^^^^^^^^^^^^^^^^^^^^^^^
  File "D:\Coding\Projects\designcrafter\designcrafter\designcrafter\views.py", line 67, in verify_otp
    login(request, user)  # Correct usage of login() function
    ^^^^^^^^^^^^^^^^^^^^
TypeError: login() takes 1 positional argument but 2 were given
2023-10-05 09:22:31,947 - INFO - D:\Coding\Projects\designcrafter\designcrafter\designcrafter\views.py changed, reloading.
2023-10-05 09:24:24,879 - INFO - D:\Coding\Projects\designcrafter\designcrafter\designcrafter\views.py changed, reloading.
2023-10-05 09:26:05,020 - ERROR - Internal Server Error: /verify_otp
Traceback (most recent call last):
  File "C:\python311\Lib\site-packages\django\core\handlers\exception.py", line 55, in inner
    response = get_response(request)
               ^^^^^^^^^^^^^^^^^^^^^
  File "C:\python311\Lib\site-packages\django\core\handlers\base.py", line 197, in _get_response
    response = wrapped_callback(request, *callback_args, **callback_kwargs)
               ^^^^^^^^^^^^^^^^^^^^^^^^^^^^^^^^^^^^^^^^^^^^^^^^^^^^^^^^^^^^
  File "D:\Coding\Projects\designcrafter\designcrafter\designcrafter\views.py", line 67, in verify_otp
    login(request, user)
TypeError: login() takes 1 positional argument but 2 were given
2023-10-05 09:26:28,357 - ERROR - Internal Server Error: /verify_otp
Traceback (most recent call last):
  File "C:\python311\Lib\site-packages\django\core\handlers\exception.py", line 55, in inner
    response = get_response(request)
               ^^^^^^^^^^^^^^^^^^^^^
  File "C:\python311\Lib\site-packages\django\core\handlers\base.py", line 197, in _get_response
    response = wrapped_callback(request, *callback_args, **callback_kwargs)
               ^^^^^^^^^^^^^^^^^^^^^^^^^^^^^^^^^^^^^^^^^^^^^^^^^^^^^^^^^^^^
  File "D:\Coding\Projects\designcrafter\designcrafter\designcrafter\views.py", line 67, in verify_otp
    login(request, user)
TypeError: login() takes 1 positional argument but 2 were given
2023-10-05 09:28:03,140 - INFO - D:\Coding\Projects\designcrafter\designcrafter\designcrafter\views.py changed, reloading.
2023-10-05 09:28:07,853 - ERROR - Internal Server Error: /verify_otp
Traceback (most recent call last):
  File "C:\python311\Lib\site-packages\django\core\handlers\exception.py", line 55, in inner
    response = get_response(request)
               ^^^^^^^^^^^^^^^^^^^^^
  File "C:\python311\Lib\site-packages\django\core\handlers\base.py", line 197, in _get_response
    response = wrapped_callback(request, *callback_args, **callback_kwargs)
               ^^^^^^^^^^^^^^^^^^^^^^^^^^^^^^^^^^^^^^^^^^^^^^^^^^^^^^^^^^^^
  File "D:\Coding\Projects\designcrafter\designcrafter\designcrafter\views.py", line 67, in verify_otp
    login(request, user)
TypeError: login() takes 1 positional argument but 2 were given
2023-10-05 09:35:00,497 - INFO - D:\Coding\Projects\designcrafter\designcrafter\designcrafter\views.py changed, reloading.
2023-10-05 09:35:08,115 - ERROR - Internal Server Error: /verify_otp
Traceback (most recent call last):
  File "C:\python311\Lib\site-packages\django\core\handlers\exception.py", line 55, in inner
    response = get_response(request)
               ^^^^^^^^^^^^^^^^^^^^^
  File "C:\python311\Lib\site-packages\django\core\handlers\base.py", line 197, in _get_response
    response = wrapped_callback(request, *callback_args, **callback_kwargs)
               ^^^^^^^^^^^^^^^^^^^^^^^^^^^^^^^^^^^^^^^^^^^^^^^^^^^^^^^^^^^^
  File "D:\Coding\Projects\designcrafter\designcrafter\designcrafter\views.py", line 67, in verify_otp
    login(request, user)
TypeError: login() takes 1 positional argument but 2 were given
2023-10-05 09:35:12,100 - ERROR - Internal Server Error: /user_login
Traceback (most recent call last):
  File "C:\python311\Lib\site-packages\django\core\handlers\exception.py", line 55, in inner
    response = get_response(request)
               ^^^^^^^^^^^^^^^^^^^^^
  File "C:\python311\Lib\site-packages\django\core\handlers\base.py", line 197, in _get_response
    response = wrapped_callback(request, *callback_args, **callback_kwargs)
               ^^^^^^^^^^^^^^^^^^^^^^^^^^^^^^^^^^^^^^^^^^^^^^^^^^^^^^^^^^^^
TypeError: user_login() missing 1 required positional argument: 'user'
2023-10-05 09:35:15,311 - WARNING - Not Found: /
2023-10-05 09:35:22,523 - ERROR - Internal Server Error: /user_login
Traceback (most recent call last):
  File "C:\python311\Lib\site-packages\django\core\handlers\exception.py", line 55, in inner
    response = get_response(request)
               ^^^^^^^^^^^^^^^^^^^^^
  File "C:\python311\Lib\site-packages\django\core\handlers\base.py", line 197, in _get_response
    response = wrapped_callback(request, *callback_args, **callback_kwargs)
               ^^^^^^^^^^^^^^^^^^^^^^^^^^^^^^^^^^^^^^^^^^^^^^^^^^^^^^^^^^^^
TypeError: user_login() missing 1 required positional argument: 'user'
2023-10-05 09:35:31,505 - INFO - D:\Coding\Projects\designcrafter\designcrafter\designcrafter\views.py changed, reloading.
2023-10-05 09:35:40,823 - INFO - D:\Coding\Projects\designcrafter\designcrafter\designcrafter\views.py changed, reloading.
2023-10-05 09:35:59,611 - ERROR - Internal Server Error: /verify_otp
Traceback (most recent call last):
  File "C:\python311\Lib\site-packages\django\core\handlers\exception.py", line 55, in inner
    response = get_response(request)
               ^^^^^^^^^^^^^^^^^^^^^
  File "C:\python311\Lib\site-packages\django\core\handlers\base.py", line 197, in _get_response
    response = wrapped_callback(request, *callback_args, **callback_kwargs)
               ^^^^^^^^^^^^^^^^^^^^^^^^^^^^^^^^^^^^^^^^^^^^^^^^^^^^^^^^^^^^
TypeError: verify_otp() missing 1 required positional argument: 'user'
2023-10-05 09:36:42,824 - INFO - D:\Coding\Projects\designcrafter\designcrafter\designcrafter\views.py changed, reloading.
2023-10-05 09:36:44,835 - ERROR - Internal Server Error: /verify_otp
Traceback (most recent call last):
  File "C:\python311\Lib\site-packages\django\core\handlers\exception.py", line 55, in inner
    response = get_response(request)
               ^^^^^^^^^^^^^^^^^^^^^
  File "C:\python311\Lib\site-packages\django\core\handlers\base.py", line 197, in _get_response
    response = wrapped_callback(request, *callback_args, **callback_kwargs)
               ^^^^^^^^^^^^^^^^^^^^^^^^^^^^^^^^^^^^^^^^^^^^^^^^^^^^^^^^^^^^
TypeError: verify_otp() missing 1 required positional argument: 'user'
2023-10-05 09:36:48,136 - INFO - D:\Coding\Projects\designcrafter\designcrafter\designcrafter\views.py changed, reloading.
2023-10-05 09:37:17,623 - ERROR - Internal Server Error: /verify_otp
Traceback (most recent call last):
  File "C:\python311\Lib\site-packages\django\core\handlers\exception.py", line 55, in inner
    response = get_response(request)
               ^^^^^^^^^^^^^^^^^^^^^
  File "C:\python311\Lib\site-packages\django\core\handlers\base.py", line 197, in _get_response
    response = wrapped_callback(request, *callback_args, **callback_kwargs)
               ^^^^^^^^^^^^^^^^^^^^^^^^^^^^^^^^^^^^^^^^^^^^^^^^^^^^^^^^^^^^
TypeError: verify_otp() missing 1 required positional argument: 'user'
2023-10-05 09:38:13,597 - INFO - D:\Coding\Projects\designcrafter\designcrafter\designcrafter\views.py changed, reloading.
2023-10-05 09:38:19,453 - ERROR - Internal Server Error: /verify_otp
Traceback (most recent call last):
  File "C:\python311\Lib\site-packages\django\core\handlers\exception.py", line 55, in inner
    response = get_response(request)
               ^^^^^^^^^^^^^^^^^^^^^
  File "C:\python311\Lib\site-packages\django\core\handlers\base.py", line 197, in _get_response
    response = wrapped_callback(request, *callback_args, **callback_kwargs)
               ^^^^^^^^^^^^^^^^^^^^^^^^^^^^^^^^^^^^^^^^^^^^^^^^^^^^^^^^^^^^
  File "D:\Coding\Projects\designcrafter\designcrafter\designcrafter\views.py", line 67, in verify_otp
    login(request, user)
TypeError: login() takes 1 positional argument but 2 were given
2023-10-05 09:38:34,201 - INFO - D:\Coding\Projects\designcrafter\designcrafter\designcrafter\views.py changed, reloading.
2023-10-05 09:38:38,376 - ERROR - Internal Server Error: /verify_otp
Traceback (most recent call last):
  File "C:\python311\Lib\site-packages\django\core\handlers\exception.py", line 55, in inner
    response = get_response(request)
               ^^^^^^^^^^^^^^^^^^^^^
  File "C:\python311\Lib\site-packages\django\core\handlers\base.py", line 197, in _get_response
    response = wrapped_callback(request, *callback_args, **callback_kwargs)
               ^^^^^^^^^^^^^^^^^^^^^^^^^^^^^^^^^^^^^^^^^^^^^^^^^^^^^^^^^^^^
  File "D:\Coding\Projects\designcrafter\designcrafter\designcrafter\views.py", line 67, in verify_otp
    login( user)
  File "D:\Coding\Projects\designcrafter\designcrafter\designcrafter\views.py", line 19, in login
    return render (request,'registration/reg_1.html')
           ^^^^^^^^^^^^^^^^^^^^^^^^^^^^^^^^^^^^^^^^^^
  File "C:\python311\Lib\site-packages\django\shortcuts.py", line 24, in render
    content = loader.render_to_string(template_name, context, request, using=using)
              ^^^^^^^^^^^^^^^^^^^^^^^^^^^^^^^^^^^^^^^^^^^^^^^^^^^^^^^^^^^^^^^^^^^^^
  File "C:\python311\Lib\site-packages\django\template\loader.py", line 62, in render_to_string
    return template.render(context, request)
           ^^^^^^^^^^^^^^^^^^^^^^^^^^^^^^^^^
  File "C:\python311\Lib\site-packages\django\template\backends\django.py", line 61, in render
    return self.template.render(context)
           ^^^^^^^^^^^^^^^^^^^^^^^^^^^^^
  File "C:\python311\Lib\site-packages\django\template\base.py", line 173, in render
    with context.bind_template(self):
  File "C:\python311\Lib\contextlib.py", line 137, in __enter__
    return next(self.gen)
           ^^^^^^^^^^^^^^
  File "C:\python311\Lib\site-packages\django\template\context.py", line 254, in bind_template
    updates.update(processor(self.request))
                   ^^^^^^^^^^^^^^^^^^^^^^^
  File "C:\python311\Lib\site-packages\django\template\context_processors.py", line 41, in debug
    if settings.DEBUG and request.META.get("REMOTE_ADDR") in settings.INTERNAL_IPS:
                          ^^^^^^^^^^^^
AttributeError: 'Newuser' object has no attribute 'META'
2023-10-05 09:38:54,134 - INFO - D:\Coding\Projects\designcrafter\designcrafter\designcrafter\views.py changed, reloading.
2023-10-05 09:39:00,199 - INFO - D:\Coding\Projects\designcrafter\designcrafter\designcrafter\views.py changed, reloading.
2023-10-05 09:39:08,350 - INFO - D:\Coding\Projects\designcrafter\designcrafter\designcrafter\views.py changed, reloading.
2023-10-05 09:39:12,351 - INFO - D:\Coding\Projects\designcrafter\designcrafter\designcrafter\views.py changed, reloading.
2023-10-05 09:39:15,446 - ERROR - Internal Server Error: /verify_otp
Traceback (most recent call last):
  File "C:\python311\Lib\site-packages\django\core\handlers\exception.py", line 55, in inner
    response = get_response(request)
               ^^^^^^^^^^^^^^^^^^^^^
  File "C:\python311\Lib\site-packages\django\core\handlers\base.py", line 197, in _get_response
    response = wrapped_callback(request, *callback_args, **callback_kwargs)
               ^^^^^^^^^^^^^^^^^^^^^^^^^^^^^^^^^^^^^^^^^^^^^^^^^^^^^^^^^^^^
TypeError: verify_otp() missing 1 required positional argument: 'user'
2023-10-05 09:40:09,226 - INFO - D:\Coding\Projects\designcrafter\designcrafter\designcrafter\views.py changed, reloading.
2023-10-05 09:40:12,145 - ERROR - Internal Server Error: /verify_otp
Traceback (most recent call last):
  File "C:\python311\Lib\site-packages\django\core\handlers\exception.py", line 55, in inner
    response = get_response(request)
               ^^^^^^^^^^^^^^^^^^^^^
  File "C:\python311\Lib\site-packages\django\core\handlers\base.py", line 197, in _get_response
    response = wrapped_callback(request, *callback_args, **callback_kwargs)
               ^^^^^^^^^^^^^^^^^^^^^^^^^^^^^^^^^^^^^^^^^^^^^^^^^^^^^^^^^^^^
TypeError: verify_otp() missing 2 required positional arguments: 'user' and 'login'
2023-10-05 09:40:18,526 - INFO - D:\Coding\Projects\designcrafter\designcrafter\designcrafter\views.py changed, reloading.
2023-10-05 09:42:23,713 - INFO - D:\Coding\Projects\designcrafter\designcrafter\designcrafter\views.py changed, reloading.
2023-10-05 09:42:29,388 - ERROR - Internal Server Error: /verify_otp
Traceback (most recent call last):
  File "C:\python311\Lib\site-packages\django\core\handlers\exception.py", line 55, in inner
    response = get_response(request)
               ^^^^^^^^^^^^^^^^^^^^^
  File "C:\python311\Lib\site-packages\django\core\handlers\base.py", line 197, in _get_response
    response = wrapped_callback(request, *callback_args, **callback_kwargs)
               ^^^^^^^^^^^^^^^^^^^^^^^^^^^^^^^^^^^^^^^^^^^^^^^^^^^^^^^^^^^^
TypeError: verify_otp() missing 1 required positional argument: 'user'
2023-10-05 09:42:36,036 - ERROR - Internal Server Error: /verify_otp
Traceback (most recent call last):
  File "C:\python311\Lib\site-packages\django\core\handlers\exception.py", line 55, in inner
    response = get_response(request)
               ^^^^^^^^^^^^^^^^^^^^^
  File "C:\python311\Lib\site-packages\django\core\handlers\base.py", line 197, in _get_response
    response = wrapped_callback(request, *callback_args, **callback_kwargs)
               ^^^^^^^^^^^^^^^^^^^^^^^^^^^^^^^^^^^^^^^^^^^^^^^^^^^^^^^^^^^^
TypeError: verify_otp() missing 1 required positional argument: 'user'
2023-10-05 09:45:45,163 - INFO - D:\Coding\Projects\designcrafter\designcrafter\designcrafter\views.py changed, reloading.
2023-10-05 09:45:51,877 - ERROR - Internal Server Error: /verify_otp
Traceback (most recent call last):
  File "C:\python311\Lib\site-packages\django\core\handlers\exception.py", line 55, in inner
    response = get_response(request)
               ^^^^^^^^^^^^^^^^^^^^^
  File "C:\python311\Lib\site-packages\django\core\handlers\base.py", line 197, in _get_response
    response = wrapped_callback(request, *callback_args, **callback_kwargs)
               ^^^^^^^^^^^^^^^^^^^^^^^^^^^^^^^^^^^^^^^^^^^^^^^^^^^^^^^^^^^^
TypeError: verify_otp() missing 1 required positional argument: 'user'
2023-10-05 09:46:27,350 - ERROR - Internal Server Error: /verify_otp
Traceback (most recent call last):
  File "C:\python311\Lib\site-packages\django\core\handlers\exception.py", line 55, in inner
    response = get_response(request)
               ^^^^^^^^^^^^^^^^^^^^^
  File "C:\python311\Lib\site-packages\django\core\handlers\base.py", line 197, in _get_response
    response = wrapped_callback(request, *callback_args, **callback_kwargs)
               ^^^^^^^^^^^^^^^^^^^^^^^^^^^^^^^^^^^^^^^^^^^^^^^^^^^^^^^^^^^^
TypeError: verify_otp() missing 1 required positional argument: 'user'
2023-10-05 09:46:43,036 - INFO - D:\Coding\Projects\designcrafter\designcrafter\designcrafter\views.py changed, reloading.
2023-10-05 09:46:52,306 - ERROR - Internal Server Error: /verify_otp
Traceback (most recent call last):
  File "C:\python311\Lib\site-packages\django\core\handlers\exception.py", line 55, in inner
    response = get_response(request)
               ^^^^^^^^^^^^^^^^^^^^^
  File "C:\python311\Lib\site-packages\django\core\handlers\base.py", line 197, in _get_response
    response = wrapped_callback(request, *callback_args, **callback_kwargs)
               ^^^^^^^^^^^^^^^^^^^^^^^^^^^^^^^^^^^^^^^^^^^^^^^^^^^^^^^^^^^^
  File "D:\Coding\Projects\designcrafter\designcrafter\designcrafter\views.py", line 61, in verify_otp
    return HttpResponse(user)
           ^^^^^^^^^^^^^^^^^^
  File "C:\python311\Lib\site-packages\django\http\response.py", line 376, in __init__
    self.content = content
    ^^^^^^^^^^^^
  File "C:\python311\Lib\site-packages\django\http\response.py", line 408, in content
    content = self.make_bytes(value)
              ^^^^^^^^^^^^^^^^^^^^^^
  File "C:\python311\Lib\site-packages\django\http\response.py", line 319, in make_bytes
    return str(value).encode(self.charset)
           ^^^^^^^^^^
  File "C:\python311\Lib\site-packages\django\contrib\auth\base_user.py", line 73, in __str__
    return self.get_username()
           ^^^^^^^^^^^^^^^^^^^
  File "C:\python311\Lib\site-packages\django\contrib\auth\base_user.py", line 83, in get_username
    return getattr(self, self.USERNAME_FIELD)
                         ^^^^^^^^^^^^^^^^^^^
AttributeError: 'Newuser' object has no attribute 'USERNAME_FIELD'
2023-10-05 09:48:03,298 - INFO - D:\Coding\Projects\designcrafter\designcrafter\designcrafter\models.py changed, reloading.
2023-10-05 09:51:32,282 - INFO - D:\Coding\Projects\designcrafter\designcrafter\designcrafter\models.py changed, reloading.
2023-10-05 09:51:38,172 - WARNING - Not Found: /favicon.ico
2023-10-05 09:55:46,179 - INFO - D:\Coding\Projects\designcrafter\designcrafter\designcrafter\views.py changed, reloading.
2023-10-05 09:55:51,683 - WARNING - Not Found: /favicon.ico
2023-10-05 09:57:37,256 - INFO - D:\Coding\Projects\designcrafter\designcrafter\designcrafter\views.py changed, reloading.
2023-10-05 10:10:48,152 - INFO - D:\Coding\Projects\designcrafter\designcrafter\designcrafter\urls.py changed, reloading.
2023-10-05 10:10:58,287 - INFO - D:\Coding\Projects\designcrafter\designcrafter\designcrafter\views.py changed, reloading.
2023-10-05 10:12:33,774 - INFO - D:\Coding\Projects\designcrafter\designcrafter\designcrafter\views.py changed, reloading.
2023-10-05 10:13:10,683 - INFO - D:\Coding\Projects\designcrafter\designcrafter\designcrafter\views.py changed, reloading.
2023-10-05 10:14:16,343 - INFO - D:\Coding\Projects\designcrafter\designcrafter\designcrafter\views.py changed, reloading.
2023-10-05 10:14:36,819 - INFO - D:\Coding\Projects\designcrafter\designcrafter\designcrafter\models.py changed, reloading.
2023-10-05 10:15:44,731 - INFO - D:\Coding\Projects\designcrafter\designcrafter\designcrafter\views.py changed, reloading.
2023-10-05 10:17:41,893 - ERROR - Internal Server Error: /verify_otp
Traceback (most recent call last):
  File "C:\python311\Lib\site-packages\django\db\backends\utils.py", line 89, in _execute
    return self.cursor.execute(sql, params)
           ^^^^^^^^^^^^^^^^^^^^^^^^^^^^^^^^
  File "C:\python311\Lib\site-packages\django\db\backends\mysql\base.py", line 75, in execute
    return self.cursor.execute(query, args)
           ^^^^^^^^^^^^^^^^^^^^^^^^^^^^^^^^
  File "C:\python311\Lib\site-packages\MySQLdb\cursors.py", line 206, in execute
    res = self._query(query)
          ^^^^^^^^^^^^^^^^^^
  File "C:\python311\Lib\site-packages\MySQLdb\cursors.py", line 319, in _query
    db.query(q)
  File "C:\python311\Lib\site-packages\MySQLdb\connections.py", line 254, in query
    _mysql.connection.query(self, query)
MySQLdb.OperationalError: (1054, "Unknown column 'dc_user_data.user_name' in 'field list'")

The above exception was the direct cause of the following exception:

Traceback (most recent call last):
  File "C:\python311\Lib\site-packages\django\core\handlers\exception.py", line 55, in inner
    response = get_response(request)
               ^^^^^^^^^^^^^^^^^^^^^
  File "C:\python311\Lib\site-packages\django\core\handlers\base.py", line 197, in _get_response
    response = wrapped_callback(request, *callback_args, **callback_kwargs)
               ^^^^^^^^^^^^^^^^^^^^^^^^^^^^^^^^^^^^^^^^^^^^^^^^^^^^^^^^^^^^
  File "D:\Coding\Projects\designcrafter\designcrafter\designcrafter\views.py", line 74, in verify_otp
    user = Newuser.objects.get(user_email=us)
           ^^^^^^^^^^^^^^^^^^^^^^^^^^^^^^^^^^
  File "C:\python311\Lib\site-packages\django\db\models\manager.py", line 87, in manager_method
    return getattr(self.get_queryset(), name)(*args, **kwargs)
           ^^^^^^^^^^^^^^^^^^^^^^^^^^^^^^^^^^^^^^^^^^^^^^^^^^^
  File "C:\python311\Lib\site-packages\django\db\models\query.py", line 633, in get
    num = len(clone)
          ^^^^^^^^^^
  File "C:\python311\Lib\site-packages\django\db\models\query.py", line 380, in __len__
    self._fetch_all()
  File "C:\python311\Lib\site-packages\django\db\models\query.py", line 1881, in _fetch_all
    self._result_cache = list(self._iterable_class(self))
                         ^^^^^^^^^^^^^^^^^^^^^^^^^^^^^^^^
  File "C:\python311\Lib\site-packages\django\db\models\query.py", line 91, in __iter__
    results = compiler.execute_sql(
              ^^^^^^^^^^^^^^^^^^^^^
  File "C:\python311\Lib\site-packages\django\db\models\sql\compiler.py", line 1562, in execute_sql
    cursor.execute(sql, params)
  File "C:\python311\Lib\site-packages\django\db\backends\utils.py", line 102, in execute
    return super().execute(sql, params)
           ^^^^^^^^^^^^^^^^^^^^^^^^^^^^
  File "C:\python311\Lib\site-packages\django\db\backends\utils.py", line 67, in execute
    return self._execute_with_wrappers(
           ^^^^^^^^^^^^^^^^^^^^^^^^^^^^
  File "C:\python311\Lib\site-packages\django\db\backends\utils.py", line 80, in _execute_with_wrappers
    return executor(sql, params, many, context)
           ^^^^^^^^^^^^^^^^^^^^^^^^^^^^^^^^^^^^
  File "C:\python311\Lib\site-packages\django\db\backends\utils.py", line 84, in _execute
    with self.db.wrap_database_errors:
  File "C:\python311\Lib\site-packages\django\db\utils.py", line 91, in __exit__
    raise dj_exc_value.with_traceback(traceback) from exc_value
  File "C:\python311\Lib\site-packages\django\db\backends\utils.py", line 89, in _execute
    return self.cursor.execute(sql, params)
           ^^^^^^^^^^^^^^^^^^^^^^^^^^^^^^^^
  File "C:\python311\Lib\site-packages\django\db\backends\mysql\base.py", line 75, in execute
    return self.cursor.execute(query, args)
           ^^^^^^^^^^^^^^^^^^^^^^^^^^^^^^^^
  File "C:\python311\Lib\site-packages\MySQLdb\cursors.py", line 206, in execute
    res = self._query(query)
          ^^^^^^^^^^^^^^^^^^
  File "C:\python311\Lib\site-packages\MySQLdb\cursors.py", line 319, in _query
    db.query(q)
  File "C:\python311\Lib\site-packages\MySQLdb\connections.py", line 254, in query
    _mysql.connection.query(self, query)
django.db.utils.OperationalError: (1054, "Unknown column 'dc_user_data.user_name' in 'field list'")
2023-10-05 10:18:05,718 - INFO - D:\Coding\Projects\designcrafter\designcrafter\designcrafter\models.py changed, reloading.
2023-10-05 10:18:39,641 - INFO - D:\Coding\Projects\designcrafter\designcrafter\designcrafter\views.py changed, reloading.
2023-10-05 10:18:51,199 - ERROR - Internal Server Error: /verify_otp
Traceback (most recent call last):
  File "C:\python311\Lib\site-packages\django\core\handlers\exception.py", line 55, in inner
    response = get_response(request)
               ^^^^^^^^^^^^^^^^^^^^^
  File "C:\python311\Lib\site-packages\django\core\handlers\base.py", line 197, in _get_response
    response = wrapped_callback(request, *callback_args, **callback_kwargs)
               ^^^^^^^^^^^^^^^^^^^^^^^^^^^^^^^^^^^^^^^^^^^^^^^^^^^^^^^^^^^^
  File "D:\Coding\Projects\designcrafter\designcrafter\designcrafter\views.py", line 80, in verify_otp
    if user.user_otp == ps:
       ^^^^^^^^^^^^^
AttributeError: 'NoneType' object has no attribute 'user_otp'
2023-10-05 10:22:04,295 - INFO - D:\Coding\Projects\designcrafter\designcrafter\designcrafter\views.py changed, reloading.
2023-10-05 10:24:16,484 - ERROR - Internal Server Error: /verify_otp
Traceback (most recent call last):
  File "C:\python311\Lib\site-packages\django\core\handlers\exception.py", line 55, in inner
    response = get_response(request)
               ^^^^^^^^^^^^^^^^^^^^^
  File "C:\python311\Lib\site-packages\django\core\handlers\base.py", line 197, in _get_response
    response = wrapped_callback(request, *callback_args, **callback_kwargs)
               ^^^^^^^^^^^^^^^^^^^^^^^^^^^^^^^^^^^^^^^^^^^^^^^^^^^^^^^^^^^^
  File "D:\Coding\Projects\designcrafter\designcrafter\designcrafter\views.py", line 80, in verify_otp
    if user.user_otp == ps:
       ^^^^^^^^^^^^^
AttributeError: 'NoneType' object has no attribute 'user_otp'
2023-10-05 10:24:19,168 - ERROR - Internal Server Error: /verify_otp
Traceback (most recent call last):
  File "C:\python311\Lib\site-packages\django\core\handlers\exception.py", line 55, in inner
    response = get_response(request)
               ^^^^^^^^^^^^^^^^^^^^^
  File "C:\python311\Lib\site-packages\django\core\handlers\base.py", line 197, in _get_response
    response = wrapped_callback(request, *callback_args, **callback_kwargs)
               ^^^^^^^^^^^^^^^^^^^^^^^^^^^^^^^^^^^^^^^^^^^^^^^^^^^^^^^^^^^^
  File "D:\Coding\Projects\designcrafter\designcrafter\designcrafter\views.py", line 80, in verify_otp
    if user.user_otp == ps:
       ^^^^^^^^^^^^^
AttributeError: 'NoneType' object has no attribute 'user_otp'
2023-10-05 10:28:47,332 - INFO - D:\Coding\Projects\designcrafter\designcrafter\designcrafter\views.py changed, reloading.
2023-10-05 10:29:00,636 - INFO - D:\Coding\Projects\designcrafter\designcrafter\designcrafter\views.py changed, reloading.
2023-10-05 10:29:44,681 - INFO - D:\Coding\Projects\designcrafter\designcrafter\designcrafter\views.py changed, reloading.
2023-10-05 10:36:21,548 - ERROR - Internal Server Error: /verify_otp
Traceback (most recent call last):
  File "C:\python311\Lib\site-packages\django\core\handlers\exception.py", line 55, in inner
    response = get_response(request)
               ^^^^^^^^^^^^^^^^^^^^^
  File "C:\python311\Lib\site-packages\django\core\handlers\base.py", line 197, in _get_response
    response = wrapped_callback(request, *callback_args, **callback_kwargs)
               ^^^^^^^^^^^^^^^^^^^^^^^^^^^^^^^^^^^^^^^^^^^^^^^^^^^^^^^^^^^^
  File "D:\Coding\Projects\designcrafter\designcrafter\designcrafter\views.py", line 80, in verify_otp
    if user.user_otp == ps:
       ^^^^^^^^^^^^^
AttributeError: 'NoneType' object has no attribute 'user_otp'
2023-10-05 10:37:59,020 - INFO - D:\Coding\Projects\designcrafter\designcrafter\designcrafter\views.py changed, reloading.
2023-10-05 10:38:11,296 - INFO - D:\Coding\Projects\designcrafter\designcrafter\designcrafter\models.py changed, reloading.
2023-10-05 10:39:38,710 - INFO - D:\Coding\Projects\designcrafter\designcrafter\designcrafter\views.py changed, reloading.
2023-10-05 10:41:47,244 - INFO - D:\Coding\Projects\designcrafter\designcrafter\designcrafter\views.py changed, reloading.
2023-10-05 10:42:04,627 - INFO - D:\Coding\Projects\designcrafter\designcrafter\designcrafter\views.py changed, reloading.
2023-10-05 11:11:17,790 - INFO - D:\Coding\Projects\designcrafter\designcrafter\designcrafter\views.py changed, reloading.
2023-10-05 11:14:43,665 - INFO - D:\Coding\Projects\designcrafter\designcrafter\designcrafter\views.py changed, reloading.
2023-10-05 11:15:06,352 - WARNING - Not Found: /
2023-10-05 11:15:38,991 - ERROR - Internal Server Error: /sendotp
Traceback (most recent call last):
  File "D:\Coding\Projects\designcrafter\designcrafter\designcrafter\views.py", line 27, in sendotp
    username1 = Newuser.objects.get(user_name=user_names)
                ^^^^^^^^^^^^^^^^^^^^^^^^^^^^^^^^^^^^^^^^^
  File "C:\python311\Lib\site-packages\django\db\models\manager.py", line 87, in manager_method
    return getattr(self.get_queryset(), name)(*args, **kwargs)
           ^^^^^^^^^^^^^^^^^^^^^^^^^^^^^^^^^^^^^^^^^^^^^^^^^^^
  File "C:\python311\Lib\site-packages\django\db\models\query.py", line 623, in get
    clone = self._chain() if self.query.combinator else self.filter(*args, **kwargs)
                                                        ^^^^^^^^^^^^^^^^^^^^^^^^^^^^
  File "C:\python311\Lib\site-packages\django\db\models\query.py", line 1436, in filter
    return self._filter_or_exclude(False, args, kwargs)
           ^^^^^^^^^^^^^^^^^^^^^^^^^^^^^^^^^^^^^^^^^^^^
  File "C:\python311\Lib\site-packages\django\db\models\query.py", line 1454, in _filter_or_exclude
    clone._filter_or_exclude_inplace(negate, args, kwargs)
  File "C:\python311\Lib\site-packages\django\db\models\query.py", line 1461, in _filter_or_exclude_inplace
    self._query.add_q(Q(*args, **kwargs))
  File "C:\python311\Lib\site-packages\django\db\models\sql\query.py", line 1534, in add_q
    clause, _ = self._add_q(q_object, self.used_aliases)
                ^^^^^^^^^^^^^^^^^^^^^^^^^^^^^^^^^^^^^^^^
  File "C:\python311\Lib\site-packages\django\db\models\sql\query.py", line 1565, in _add_q
    child_clause, needed_inner = self.build_filter(
                                 ^^^^^^^^^^^^^^^^^^
  File "C:\python311\Lib\site-packages\django\db\models\sql\query.py", line 1415, in build_filter
    lookups, parts, reffed_expression = self.solve_lookup_type(arg, summarize)
                                        ^^^^^^^^^^^^^^^^^^^^^^^^^^^^^^^^^^^^^^
  File "C:\python311\Lib\site-packages\django\db\models\sql\query.py", line 1225, in solve_lookup_type
    _, field, _, lookup_parts = self.names_to_path(lookup_splitted, self.get_meta())
                                ^^^^^^^^^^^^^^^^^^^^^^^^^^^^^^^^^^^^^^^^^^^^^^^^^^^^
  File "C:\python311\Lib\site-packages\django\db\models\sql\query.py", line 1713, in names_to_path
    raise FieldError(
django.core.exceptions.FieldError: Cannot resolve keyword 'user_name' into field. Choices are: id, status, user_email, user_mobile, user_otp, username, visits

During handling of the above exception, another exception occurred:

Traceback (most recent call last):
  File "C:\python311\Lib\site-packages\django\core\handlers\exception.py", line 55, in inner
    response = get_response(request)
               ^^^^^^^^^^^^^^^^^^^^^
  File "C:\python311\Lib\site-packages\django\core\handlers\base.py", line 197, in _get_response
    response = wrapped_callback(request, *callback_args, **callback_kwargs)
               ^^^^^^^^^^^^^^^^^^^^^^^^^^^^^^^^^^^^^^^^^^^^^^^^^^^^^^^^^^^^
  File "D:\Coding\Projects\designcrafter\designcrafter\designcrafter\views.py", line 40, in sendotp
    user1 = Newuser(user_name=user_names, user_email=user_emails, user_otp=otp)
            ^^^^^^^^^^^^^^^^^^^^^^^^^^^^^^^^^^^^^^^^^^^^^^^^^^^^^^^^^^^^^^^^^^^
  File "C:\python311\Lib\site-packages\django\db\models\base.py", line 567, in __init__
    raise TypeError(
TypeError: Newuser() got unexpected keyword arguments: 'user_name'
2023-10-05 11:15:53,083 - INFO - D:\Coding\Projects\designcrafter\designcrafter\designcrafter\models.py changed, reloading.
2023-10-05 11:15:55,131 - ERROR - Internal Server Error: /sendotp
Traceback (most recent call last):
  File "C:\python311\Lib\site-packages\django\db\backends\utils.py", line 89, in _execute
    return self.cursor.execute(sql, params)
           ^^^^^^^^^^^^^^^^^^^^^^^^^^^^^^^^
  File "C:\python311\Lib\site-packages\django\db\backends\mysql\base.py", line 75, in execute
    return self.cursor.execute(query, args)
           ^^^^^^^^^^^^^^^^^^^^^^^^^^^^^^^^
  File "C:\python311\Lib\site-packages\MySQLdb\cursors.py", line 206, in execute
    res = self._query(query)
          ^^^^^^^^^^^^^^^^^^
  File "C:\python311\Lib\site-packages\MySQLdb\cursors.py", line 319, in _query
    db.query(q)
  File "C:\python311\Lib\site-packages\MySQLdb\connections.py", line 254, in query
    _mysql.connection.query(self, query)
MySQLdb.OperationalError: (1054, "Unknown column 'dc_user_data.user_name' in 'field list'")

The above exception was the direct cause of the following exception:

Traceback (most recent call last):
  File "D:\Coding\Projects\designcrafter\designcrafter\designcrafter\views.py", line 27, in sendotp
    username1 = Newuser.objects.get(user_name=user_names)
                ^^^^^^^^^^^^^^^^^^^^^^^^^^^^^^^^^^^^^^^^^
  File "C:\python311\Lib\site-packages\django\db\models\manager.py", line 87, in manager_method
    return getattr(self.get_queryset(), name)(*args, **kwargs)
           ^^^^^^^^^^^^^^^^^^^^^^^^^^^^^^^^^^^^^^^^^^^^^^^^^^^
  File "C:\python311\Lib\site-packages\django\db\models\query.py", line 633, in get
    num = len(clone)
          ^^^^^^^^^^
  File "C:\python311\Lib\site-packages\django\db\models\query.py", line 380, in __len__
    self._fetch_all()
  File "C:\python311\Lib\site-packages\django\db\models\query.py", line 1881, in _fetch_all
    self._result_cache = list(self._iterable_class(self))
                         ^^^^^^^^^^^^^^^^^^^^^^^^^^^^^^^^
  File "C:\python311\Lib\site-packages\django\db\models\query.py", line 91, in __iter__
    results = compiler.execute_sql(
              ^^^^^^^^^^^^^^^^^^^^^
  File "C:\python311\Lib\site-packages\django\db\models\sql\compiler.py", line 1562, in execute_sql
    cursor.execute(sql, params)
  File "C:\python311\Lib\site-packages\django\db\backends\utils.py", line 102, in execute
    return super().execute(sql, params)
           ^^^^^^^^^^^^^^^^^^^^^^^^^^^^
  File "C:\python311\Lib\site-packages\django\db\backends\utils.py", line 67, in execute
    return self._execute_with_wrappers(
           ^^^^^^^^^^^^^^^^^^^^^^^^^^^^
  File "C:\python311\Lib\site-packages\django\db\backends\utils.py", line 80, in _execute_with_wrappers
    return executor(sql, params, many, context)
           ^^^^^^^^^^^^^^^^^^^^^^^^^^^^^^^^^^^^
  File "C:\python311\Lib\site-packages\django\db\backends\utils.py", line 84, in _execute
    with self.db.wrap_database_errors:
  File "C:\python311\Lib\site-packages\django\db\utils.py", line 91, in __exit__
    raise dj_exc_value.with_traceback(traceback) from exc_value
  File "C:\python311\Lib\site-packages\django\db\backends\utils.py", line 89, in _execute
    return self.cursor.execute(sql, params)
           ^^^^^^^^^^^^^^^^^^^^^^^^^^^^^^^^
  File "C:\python311\Lib\site-packages\django\db\backends\mysql\base.py", line 75, in execute
    return self.cursor.execute(query, args)
           ^^^^^^^^^^^^^^^^^^^^^^^^^^^^^^^^
  File "C:\python311\Lib\site-packages\MySQLdb\cursors.py", line 206, in execute
    res = self._query(query)
          ^^^^^^^^^^^^^^^^^^
  File "C:\python311\Lib\site-packages\MySQLdb\cursors.py", line 319, in _query
    db.query(q)
  File "C:\python311\Lib\site-packages\MySQLdb\connections.py", line 254, in query
    _mysql.connection.query(self, query)
django.db.utils.OperationalError: (1054, "Unknown column 'dc_user_data.user_name' in 'field list'")

During handling of the above exception, another exception occurred:

Traceback (most recent call last):
  File "C:\python311\Lib\site-packages\django\db\backends\utils.py", line 89, in _execute
    return self.cursor.execute(sql, params)
           ^^^^^^^^^^^^^^^^^^^^^^^^^^^^^^^^
  File "C:\python311\Lib\site-packages\django\db\backends\mysql\base.py", line 75, in execute
    return self.cursor.execute(query, args)
           ^^^^^^^^^^^^^^^^^^^^^^^^^^^^^^^^
  File "C:\python311\Lib\site-packages\MySQLdb\cursors.py", line 206, in execute
    res = self._query(query)
          ^^^^^^^^^^^^^^^^^^
  File "C:\python311\Lib\site-packages\MySQLdb\cursors.py", line 319, in _query
    db.query(q)
  File "C:\python311\Lib\site-packages\MySQLdb\connections.py", line 254, in query
    _mysql.connection.query(self, query)
MySQLdb.OperationalError: (1054, "Unknown column 'user_name' in 'field list'")

The above exception was the direct cause of the following exception:

Traceback (most recent call last):
  File "C:\python311\Lib\site-packages\django\core\handlers\exception.py", line 55, in inner
    response = get_response(request)
               ^^^^^^^^^^^^^^^^^^^^^
  File "C:\python311\Lib\site-packages\django\core\handlers\base.py", line 197, in _get_response
    response = wrapped_callback(request, *callback_args, **callback_kwargs)
               ^^^^^^^^^^^^^^^^^^^^^^^^^^^^^^^^^^^^^^^^^^^^^^^^^^^^^^^^^^^^
  File "D:\Coding\Projects\designcrafter\designcrafter\designcrafter\views.py", line 41, in sendotp
    user1.save()
  File "C:\python311\Lib\site-packages\django\db\models\base.py", line 814, in save
    self.save_base(
  File "C:\python311\Lib\site-packages\django\db\models\base.py", line 877, in save_base
    updated = self._save_table(
              ^^^^^^^^^^^^^^^^^
  File "C:\python311\Lib\site-packages\django\db\models\base.py", line 1020, in _save_table
    results = self._do_insert(
              ^^^^^^^^^^^^^^^^
  File "C:\python311\Lib\site-packages\django\db\models\base.py", line 1061, in _do_insert
    return manager._insert(
           ^^^^^^^^^^^^^^^^
  File "C:\python311\Lib\site-packages\django\db\models\manager.py", line 87, in manager_method
    return getattr(self.get_queryset(), name)(*args, **kwargs)
           ^^^^^^^^^^^^^^^^^^^^^^^^^^^^^^^^^^^^^^^^^^^^^^^^^^^
  File "C:\python311\Lib\site-packages\django\db\models\query.py", line 1805, in _insert
    return query.get_compiler(using=using).execute_sql(returning_fields)
           ^^^^^^^^^^^^^^^^^^^^^^^^^^^^^^^^^^^^^^^^^^^^^^^^^^^^^^^^^^^^^
  File "C:\python311\Lib\site-packages\django\db\models\sql\compiler.py", line 1822, in execute_sql
    cursor.execute(sql, params)
  File "C:\python311\Lib\site-packages\django\db\backends\utils.py", line 102, in execute
    return super().execute(sql, params)
           ^^^^^^^^^^^^^^^^^^^^^^^^^^^^
  File "C:\python311\Lib\site-packages\django\db\backends\utils.py", line 67, in execute
    return self._execute_with_wrappers(
           ^^^^^^^^^^^^^^^^^^^^^^^^^^^^
  File "C:\python311\Lib\site-packages\django\db\backends\utils.py", line 80, in _execute_with_wrappers
    return executor(sql, params, many, context)
           ^^^^^^^^^^^^^^^^^^^^^^^^^^^^^^^^^^^^
  File "C:\python311\Lib\site-packages\django\db\backends\utils.py", line 84, in _execute
    with self.db.wrap_database_errors:
  File "C:\python311\Lib\site-packages\django\db\utils.py", line 91, in __exit__
    raise dj_exc_value.with_traceback(traceback) from exc_value
  File "C:\python311\Lib\site-packages\django\db\backends\utils.py", line 89, in _execute
    return self.cursor.execute(sql, params)
           ^^^^^^^^^^^^^^^^^^^^^^^^^^^^^^^^
  File "C:\python311\Lib\site-packages\django\db\backends\mysql\base.py", line 75, in execute
    return self.cursor.execute(query, args)
           ^^^^^^^^^^^^^^^^^^^^^^^^^^^^^^^^
  File "C:\python311\Lib\site-packages\MySQLdb\cursors.py", line 206, in execute
    res = self._query(query)
          ^^^^^^^^^^^^^^^^^^
  File "C:\python311\Lib\site-packages\MySQLdb\cursors.py", line 319, in _query
    db.query(q)
  File "C:\python311\Lib\site-packages\MySQLdb\connections.py", line 254, in query
    _mysql.connection.query(self, query)
django.db.utils.OperationalError: (1054, "Unknown column 'user_name' in 'field list'")
2023-10-05 11:16:26,958 - ERROR - Internal Server Error: /sendotp
Traceback (most recent call last):
  File "C:\python311\Lib\site-packages\django\db\backends\utils.py", line 89, in _execute
    return self.cursor.execute(sql, params)
           ^^^^^^^^^^^^^^^^^^^^^^^^^^^^^^^^
  File "C:\python311\Lib\site-packages\django\db\backends\mysql\base.py", line 75, in execute
    return self.cursor.execute(query, args)
           ^^^^^^^^^^^^^^^^^^^^^^^^^^^^^^^^
  File "C:\python311\Lib\site-packages\MySQLdb\cursors.py", line 206, in execute
    res = self._query(query)
          ^^^^^^^^^^^^^^^^^^
  File "C:\python311\Lib\site-packages\MySQLdb\cursors.py", line 319, in _query
    db.query(q)
  File "C:\python311\Lib\site-packages\MySQLdb\connections.py", line 254, in query
    _mysql.connection.query(self, query)
MySQLdb.OperationalError: (1054, "Unknown column 'dc_user_data.user_name' in 'field list'")

The above exception was the direct cause of the following exception:

Traceback (most recent call last):
  File "D:\Coding\Projects\designcrafter\designcrafter\designcrafter\views.py", line 27, in sendotp
    username1 = Newuser.objects.get(user_name=user_names)
                ^^^^^^^^^^^^^^^^^^^^^^^^^^^^^^^^^^^^^^^^^
  File "C:\python311\Lib\site-packages\django\db\models\manager.py", line 87, in manager_method
    return getattr(self.get_queryset(), name)(*args, **kwargs)
           ^^^^^^^^^^^^^^^^^^^^^^^^^^^^^^^^^^^^^^^^^^^^^^^^^^^
  File "C:\python311\Lib\site-packages\django\db\models\query.py", line 633, in get
    num = len(clone)
          ^^^^^^^^^^
  File "C:\python311\Lib\site-packages\django\db\models\query.py", line 380, in __len__
    self._fetch_all()
  File "C:\python311\Lib\site-packages\django\db\models\query.py", line 1881, in _fetch_all
    self._result_cache = list(self._iterable_class(self))
                         ^^^^^^^^^^^^^^^^^^^^^^^^^^^^^^^^
  File "C:\python311\Lib\site-packages\django\db\models\query.py", line 91, in __iter__
    results = compiler.execute_sql(
              ^^^^^^^^^^^^^^^^^^^^^
  File "C:\python311\Lib\site-packages\django\db\models\sql\compiler.py", line 1562, in execute_sql
    cursor.execute(sql, params)
  File "C:\python311\Lib\site-packages\django\db\backends\utils.py", line 102, in execute
    return super().execute(sql, params)
           ^^^^^^^^^^^^^^^^^^^^^^^^^^^^
  File "C:\python311\Lib\site-packages\django\db\backends\utils.py", line 67, in execute
    return self._execute_with_wrappers(
           ^^^^^^^^^^^^^^^^^^^^^^^^^^^^
  File "C:\python311\Lib\site-packages\django\db\backends\utils.py", line 80, in _execute_with_wrappers
    return executor(sql, params, many, context)
           ^^^^^^^^^^^^^^^^^^^^^^^^^^^^^^^^^^^^
  File "C:\python311\Lib\site-packages\django\db\backends\utils.py", line 84, in _execute
    with self.db.wrap_database_errors:
  File "C:\python311\Lib\site-packages\django\db\utils.py", line 91, in __exit__
    raise dj_exc_value.with_traceback(traceback) from exc_value
  File "C:\python311\Lib\site-packages\django\db\backends\utils.py", line 89, in _execute
    return self.cursor.execute(sql, params)
           ^^^^^^^^^^^^^^^^^^^^^^^^^^^^^^^^
  File "C:\python311\Lib\site-packages\django\db\backends\mysql\base.py", line 75, in execute
    return self.cursor.execute(query, args)
           ^^^^^^^^^^^^^^^^^^^^^^^^^^^^^^^^
  File "C:\python311\Lib\site-packages\MySQLdb\cursors.py", line 206, in execute
    res = self._query(query)
          ^^^^^^^^^^^^^^^^^^
  File "C:\python311\Lib\site-packages\MySQLdb\cursors.py", line 319, in _query
    db.query(q)
  File "C:\python311\Lib\site-packages\MySQLdb\connections.py", line 254, in query
    _mysql.connection.query(self, query)
django.db.utils.OperationalError: (1054, "Unknown column 'dc_user_data.user_name' in 'field list'")

During handling of the above exception, another exception occurred:

Traceback (most recent call last):
  File "C:\python311\Lib\site-packages\django\db\backends\utils.py", line 89, in _execute
    return self.cursor.execute(sql, params)
           ^^^^^^^^^^^^^^^^^^^^^^^^^^^^^^^^
  File "C:\python311\Lib\site-packages\django\db\backends\mysql\base.py", line 75, in execute
    return self.cursor.execute(query, args)
           ^^^^^^^^^^^^^^^^^^^^^^^^^^^^^^^^
  File "C:\python311\Lib\site-packages\MySQLdb\cursors.py", line 206, in execute
    res = self._query(query)
          ^^^^^^^^^^^^^^^^^^
  File "C:\python311\Lib\site-packages\MySQLdb\cursors.py", line 319, in _query
    db.query(q)
  File "C:\python311\Lib\site-packages\MySQLdb\connections.py", line 254, in query
    _mysql.connection.query(self, query)
MySQLdb.OperationalError: (1054, "Unknown column 'user_name' in 'field list'")

The above exception was the direct cause of the following exception:

Traceback (most recent call last):
  File "C:\python311\Lib\site-packages\django\core\handlers\exception.py", line 55, in inner
    response = get_response(request)
               ^^^^^^^^^^^^^^^^^^^^^
  File "C:\python311\Lib\site-packages\django\core\handlers\base.py", line 197, in _get_response
    response = wrapped_callback(request, *callback_args, **callback_kwargs)
               ^^^^^^^^^^^^^^^^^^^^^^^^^^^^^^^^^^^^^^^^^^^^^^^^^^^^^^^^^^^^
  File "D:\Coding\Projects\designcrafter\designcrafter\designcrafter\views.py", line 41, in sendotp
    user1.save()
  File "C:\python311\Lib\site-packages\django\db\models\base.py", line 814, in save
    self.save_base(
  File "C:\python311\Lib\site-packages\django\db\models\base.py", line 877, in save_base
    updated = self._save_table(
              ^^^^^^^^^^^^^^^^^
  File "C:\python311\Lib\site-packages\django\db\models\base.py", line 1020, in _save_table
    results = self._do_insert(
              ^^^^^^^^^^^^^^^^
  File "C:\python311\Lib\site-packages\django\db\models\base.py", line 1061, in _do_insert
    return manager._insert(
           ^^^^^^^^^^^^^^^^
  File "C:\python311\Lib\site-packages\django\db\models\manager.py", line 87, in manager_method
    return getattr(self.get_queryset(), name)(*args, **kwargs)
           ^^^^^^^^^^^^^^^^^^^^^^^^^^^^^^^^^^^^^^^^^^^^^^^^^^^
  File "C:\python311\Lib\site-packages\django\db\models\query.py", line 1805, in _insert
    return query.get_compiler(using=using).execute_sql(returning_fields)
           ^^^^^^^^^^^^^^^^^^^^^^^^^^^^^^^^^^^^^^^^^^^^^^^^^^^^^^^^^^^^^
  File "C:\python311\Lib\site-packages\django\db\models\sql\compiler.py", line 1822, in execute_sql
    cursor.execute(sql, params)
  File "C:\python311\Lib\site-packages\django\db\backends\utils.py", line 102, in execute
    return super().execute(sql, params)
           ^^^^^^^^^^^^^^^^^^^^^^^^^^^^
  File "C:\python311\Lib\site-packages\django\db\backends\utils.py", line 67, in execute
    return self._execute_with_wrappers(
           ^^^^^^^^^^^^^^^^^^^^^^^^^^^^
  File "C:\python311\Lib\site-packages\django\db\backends\utils.py", line 80, in _execute_with_wrappers
    return executor(sql, params, many, context)
           ^^^^^^^^^^^^^^^^^^^^^^^^^^^^^^^^^^^^
  File "C:\python311\Lib\site-packages\django\db\backends\utils.py", line 84, in _execute
    with self.db.wrap_database_errors:
  File "C:\python311\Lib\site-packages\django\db\utils.py", line 91, in __exit__
    raise dj_exc_value.with_traceback(traceback) from exc_value
  File "C:\python311\Lib\site-packages\django\db\backends\utils.py", line 89, in _execute
    return self.cursor.execute(sql, params)
           ^^^^^^^^^^^^^^^^^^^^^^^^^^^^^^^^
  File "C:\python311\Lib\site-packages\django\db\backends\mysql\base.py", line 75, in execute
    return self.cursor.execute(query, args)
           ^^^^^^^^^^^^^^^^^^^^^^^^^^^^^^^^
  File "C:\python311\Lib\site-packages\MySQLdb\cursors.py", line 206, in execute
    res = self._query(query)
          ^^^^^^^^^^^^^^^^^^
  File "C:\python311\Lib\site-packages\MySQLdb\cursors.py", line 319, in _query
    db.query(q)
  File "C:\python311\Lib\site-packages\MySQLdb\connections.py", line 254, in query
    _mysql.connection.query(self, query)
django.db.utils.OperationalError: (1054, "Unknown column 'user_name' in 'field list'")
2023-10-05 11:17:18,296 - ERROR - Internal Server Error: /sendotp
Traceback (most recent call last):
  File "C:\python311\Lib\site-packages\django\db\backends\utils.py", line 89, in _execute
    return self.cursor.execute(sql, params)
           ^^^^^^^^^^^^^^^^^^^^^^^^^^^^^^^^
  File "C:\python311\Lib\site-packages\django\db\backends\mysql\base.py", line 75, in execute
    return self.cursor.execute(query, args)
           ^^^^^^^^^^^^^^^^^^^^^^^^^^^^^^^^
  File "C:\python311\Lib\site-packages\MySQLdb\cursors.py", line 206, in execute
    res = self._query(query)
          ^^^^^^^^^^^^^^^^^^
  File "C:\python311\Lib\site-packages\MySQLdb\cursors.py", line 319, in _query
    db.query(q)
  File "C:\python311\Lib\site-packages\MySQLdb\connections.py", line 254, in query
    _mysql.connection.query(self, query)
MySQLdb.OperationalError: (1054, "Unknown column 'dc_user_data.user_name' in 'field list'")

The above exception was the direct cause of the following exception:

Traceback (most recent call last):
  File "D:\Coding\Projects\designcrafter\designcrafter\designcrafter\views.py", line 27, in sendotp
    username1 = Newuser.objects.get(user_name=user_names)
                ^^^^^^^^^^^^^^^^^^^^^^^^^^^^^^^^^^^^^^^^^
  File "C:\python311\Lib\site-packages\django\db\models\manager.py", line 87, in manager_method
    return getattr(self.get_queryset(), name)(*args, **kwargs)
           ^^^^^^^^^^^^^^^^^^^^^^^^^^^^^^^^^^^^^^^^^^^^^^^^^^^
  File "C:\python311\Lib\site-packages\django\db\models\query.py", line 633, in get
    num = len(clone)
          ^^^^^^^^^^
  File "C:\python311\Lib\site-packages\django\db\models\query.py", line 380, in __len__
    self._fetch_all()
  File "C:\python311\Lib\site-packages\django\db\models\query.py", line 1881, in _fetch_all
    self._result_cache = list(self._iterable_class(self))
                         ^^^^^^^^^^^^^^^^^^^^^^^^^^^^^^^^
  File "C:\python311\Lib\site-packages\django\db\models\query.py", line 91, in __iter__
    results = compiler.execute_sql(
              ^^^^^^^^^^^^^^^^^^^^^
  File "C:\python311\Lib\site-packages\django\db\models\sql\compiler.py", line 1562, in execute_sql
    cursor.execute(sql, params)
  File "C:\python311\Lib\site-packages\django\db\backends\utils.py", line 102, in execute
    return super().execute(sql, params)
           ^^^^^^^^^^^^^^^^^^^^^^^^^^^^
  File "C:\python311\Lib\site-packages\django\db\backends\utils.py", line 67, in execute
    return self._execute_with_wrappers(
           ^^^^^^^^^^^^^^^^^^^^^^^^^^^^
  File "C:\python311\Lib\site-packages\django\db\backends\utils.py", line 80, in _execute_with_wrappers
    return executor(sql, params, many, context)
           ^^^^^^^^^^^^^^^^^^^^^^^^^^^^^^^^^^^^
  File "C:\python311\Lib\site-packages\django\db\backends\utils.py", line 84, in _execute
    with self.db.wrap_database_errors:
  File "C:\python311\Lib\site-packages\django\db\utils.py", line 91, in __exit__
    raise dj_exc_value.with_traceback(traceback) from exc_value
  File "C:\python311\Lib\site-packages\django\db\backends\utils.py", line 89, in _execute
    return self.cursor.execute(sql, params)
           ^^^^^^^^^^^^^^^^^^^^^^^^^^^^^^^^
  File "C:\python311\Lib\site-packages\django\db\backends\mysql\base.py", line 75, in execute
    return self.cursor.execute(query, args)
           ^^^^^^^^^^^^^^^^^^^^^^^^^^^^^^^^
  File "C:\python311\Lib\site-packages\MySQLdb\cursors.py", line 206, in execute
    res = self._query(query)
          ^^^^^^^^^^^^^^^^^^
  File "C:\python311\Lib\site-packages\MySQLdb\cursors.py", line 319, in _query
    db.query(q)
  File "C:\python311\Lib\site-packages\MySQLdb\connections.py", line 254, in query
    _mysql.connection.query(self, query)
django.db.utils.OperationalError: (1054, "Unknown column 'dc_user_data.user_name' in 'field list'")

During handling of the above exception, another exception occurred:

Traceback (most recent call last):
  File "C:\python311\Lib\site-packages\django\db\backends\utils.py", line 89, in _execute
    return self.cursor.execute(sql, params)
           ^^^^^^^^^^^^^^^^^^^^^^^^^^^^^^^^
  File "C:\python311\Lib\site-packages\django\db\backends\mysql\base.py", line 75, in execute
    return self.cursor.execute(query, args)
           ^^^^^^^^^^^^^^^^^^^^^^^^^^^^^^^^
  File "C:\python311\Lib\site-packages\MySQLdb\cursors.py", line 206, in execute
    res = self._query(query)
          ^^^^^^^^^^^^^^^^^^
  File "C:\python311\Lib\site-packages\MySQLdb\cursors.py", line 319, in _query
    db.query(q)
  File "C:\python311\Lib\site-packages\MySQLdb\connections.py", line 254, in query
    _mysql.connection.query(self, query)
MySQLdb.OperationalError: (1054, "Unknown column 'user_name' in 'field list'")

The above exception was the direct cause of the following exception:

Traceback (most recent call last):
  File "C:\python311\Lib\site-packages\django\core\handlers\exception.py", line 55, in inner
    response = get_response(request)
               ^^^^^^^^^^^^^^^^^^^^^
  File "C:\python311\Lib\site-packages\django\core\handlers\base.py", line 197, in _get_response
    response = wrapped_callback(request, *callback_args, **callback_kwargs)
               ^^^^^^^^^^^^^^^^^^^^^^^^^^^^^^^^^^^^^^^^^^^^^^^^^^^^^^^^^^^^
  File "D:\Coding\Projects\designcrafter\designcrafter\designcrafter\views.py", line 41, in sendotp
    user1.save()
  File "C:\python311\Lib\site-packages\django\db\models\base.py", line 814, in save
    self.save_base(
  File "C:\python311\Lib\site-packages\django\db\models\base.py", line 877, in save_base
    updated = self._save_table(
              ^^^^^^^^^^^^^^^^^
  File "C:\python311\Lib\site-packages\django\db\models\base.py", line 1020, in _save_table
    results = self._do_insert(
              ^^^^^^^^^^^^^^^^
  File "C:\python311\Lib\site-packages\django\db\models\base.py", line 1061, in _do_insert
    return manager._insert(
           ^^^^^^^^^^^^^^^^
  File "C:\python311\Lib\site-packages\django\db\models\manager.py", line 87, in manager_method
    return getattr(self.get_queryset(), name)(*args, **kwargs)
           ^^^^^^^^^^^^^^^^^^^^^^^^^^^^^^^^^^^^^^^^^^^^^^^^^^^
  File "C:\python311\Lib\site-packages\django\db\models\query.py", line 1805, in _insert
    return query.get_compiler(using=using).execute_sql(returning_fields)
           ^^^^^^^^^^^^^^^^^^^^^^^^^^^^^^^^^^^^^^^^^^^^^^^^^^^^^^^^^^^^^
  File "C:\python311\Lib\site-packages\django\db\models\sql\compiler.py", line 1822, in execute_sql
    cursor.execute(sql, params)
  File "C:\python311\Lib\site-packages\django\db\backends\utils.py", line 102, in execute
    return super().execute(sql, params)
           ^^^^^^^^^^^^^^^^^^^^^^^^^^^^
  File "C:\python311\Lib\site-packages\django\db\backends\utils.py", line 67, in execute
    return self._execute_with_wrappers(
           ^^^^^^^^^^^^^^^^^^^^^^^^^^^^
  File "C:\python311\Lib\site-packages\django\db\backends\utils.py", line 80, in _execute_with_wrappers
    return executor(sql, params, many, context)
           ^^^^^^^^^^^^^^^^^^^^^^^^^^^^^^^^^^^^
  File "C:\python311\Lib\site-packages\django\db\backends\utils.py", line 84, in _execute
    with self.db.wrap_database_errors:
  File "C:\python311\Lib\site-packages\django\db\utils.py", line 91, in __exit__
    raise dj_exc_value.with_traceback(traceback) from exc_value
  File "C:\python311\Lib\site-packages\django\db\backends\utils.py", line 89, in _execute
    return self.cursor.execute(sql, params)
           ^^^^^^^^^^^^^^^^^^^^^^^^^^^^^^^^
  File "C:\python311\Lib\site-packages\django\db\backends\mysql\base.py", line 75, in execute
    return self.cursor.execute(query, args)
           ^^^^^^^^^^^^^^^^^^^^^^^^^^^^^^^^
  File "C:\python311\Lib\site-packages\MySQLdb\cursors.py", line 206, in execute
    res = self._query(query)
          ^^^^^^^^^^^^^^^^^^
  File "C:\python311\Lib\site-packages\MySQLdb\cursors.py", line 319, in _query
    db.query(q)
  File "C:\python311\Lib\site-packages\MySQLdb\connections.py", line 254, in query
    _mysql.connection.query(self, query)
django.db.utils.OperationalError: (1054, "Unknown column 'user_name' in 'field list'")
2023-10-05 11:17:25,963 - INFO - D:\Coding\Projects\designcrafter\designcrafter\designcrafter\models.py changed, reloading.
2023-10-05 11:18:07,109 - ERROR - Internal Server Error: /sendotp
Traceback (most recent call last):
  File "C:\python311\Lib\site-packages\django\db\backends\utils.py", line 89, in _execute
    return self.cursor.execute(sql, params)
           ^^^^^^^^^^^^^^^^^^^^^^^^^^^^^^^^
  File "C:\python311\Lib\site-packages\django\db\backends\mysql\base.py", line 75, in execute
    return self.cursor.execute(query, args)
           ^^^^^^^^^^^^^^^^^^^^^^^^^^^^^^^^
  File "C:\python311\Lib\site-packages\MySQLdb\cursors.py", line 206, in execute
    res = self._query(query)
          ^^^^^^^^^^^^^^^^^^
  File "C:\python311\Lib\site-packages\MySQLdb\cursors.py", line 319, in _query
    db.query(q)
  File "C:\python311\Lib\site-packages\MySQLdb\connections.py", line 254, in query
    _mysql.connection.query(self, query)
MySQLdb.OperationalError: (1054, "Unknown column 'dc_user_data.user_name' in 'field list'")

The above exception was the direct cause of the following exception:

Traceback (most recent call last):
  File "D:\Coding\Projects\designcrafter\designcrafter\designcrafter\views.py", line 27, in sendotp
    username1 = Newuser.objects.get(user_name=user_names)
                ^^^^^^^^^^^^^^^^^^^^^^^^^^^^^^^^^^^^^^^^^
  File "C:\python311\Lib\site-packages\django\db\models\manager.py", line 87, in manager_method
    return getattr(self.get_queryset(), name)(*args, **kwargs)
           ^^^^^^^^^^^^^^^^^^^^^^^^^^^^^^^^^^^^^^^^^^^^^^^^^^^
  File "C:\python311\Lib\site-packages\django\db\models\query.py", line 633, in get
    num = len(clone)
          ^^^^^^^^^^
  File "C:\python311\Lib\site-packages\django\db\models\query.py", line 380, in __len__
    self._fetch_all()
  File "C:\python311\Lib\site-packages\django\db\models\query.py", line 1881, in _fetch_all
    self._result_cache = list(self._iterable_class(self))
                         ^^^^^^^^^^^^^^^^^^^^^^^^^^^^^^^^
  File "C:\python311\Lib\site-packages\django\db\models\query.py", line 91, in __iter__
    results = compiler.execute_sql(
              ^^^^^^^^^^^^^^^^^^^^^
  File "C:\python311\Lib\site-packages\django\db\models\sql\compiler.py", line 1562, in execute_sql
    cursor.execute(sql, params)
  File "C:\python311\Lib\site-packages\django\db\backends\utils.py", line 102, in execute
    return super().execute(sql, params)
           ^^^^^^^^^^^^^^^^^^^^^^^^^^^^
  File "C:\python311\Lib\site-packages\django\db\backends\utils.py", line 67, in execute
    return self._execute_with_wrappers(
           ^^^^^^^^^^^^^^^^^^^^^^^^^^^^
  File "C:\python311\Lib\site-packages\django\db\backends\utils.py", line 80, in _execute_with_wrappers
    return executor(sql, params, many, context)
           ^^^^^^^^^^^^^^^^^^^^^^^^^^^^^^^^^^^^
  File "C:\python311\Lib\site-packages\django\db\backends\utils.py", line 84, in _execute
    with self.db.wrap_database_errors:
  File "C:\python311\Lib\site-packages\django\db\utils.py", line 91, in __exit__
    raise dj_exc_value.with_traceback(traceback) from exc_value
  File "C:\python311\Lib\site-packages\django\db\backends\utils.py", line 89, in _execute
    return self.cursor.execute(sql, params)
           ^^^^^^^^^^^^^^^^^^^^^^^^^^^^^^^^
  File "C:\python311\Lib\site-packages\django\db\backends\mysql\base.py", line 75, in execute
    return self.cursor.execute(query, args)
           ^^^^^^^^^^^^^^^^^^^^^^^^^^^^^^^^
  File "C:\python311\Lib\site-packages\MySQLdb\cursors.py", line 206, in execute
    res = self._query(query)
          ^^^^^^^^^^^^^^^^^^
  File "C:\python311\Lib\site-packages\MySQLdb\cursors.py", line 319, in _query
    db.query(q)
  File "C:\python311\Lib\site-packages\MySQLdb\connections.py", line 254, in query
    _mysql.connection.query(self, query)
django.db.utils.OperationalError: (1054, "Unknown column 'dc_user_data.user_name' in 'field list'")

During handling of the above exception, another exception occurred:

Traceback (most recent call last):
  File "C:\python311\Lib\site-packages\django\db\backends\utils.py", line 89, in _execute
    return self.cursor.execute(sql, params)
           ^^^^^^^^^^^^^^^^^^^^^^^^^^^^^^^^
  File "C:\python311\Lib\site-packages\django\db\backends\mysql\base.py", line 75, in execute
    return self.cursor.execute(query, args)
           ^^^^^^^^^^^^^^^^^^^^^^^^^^^^^^^^
  File "C:\python311\Lib\site-packages\MySQLdb\cursors.py", line 206, in execute
    res = self._query(query)
          ^^^^^^^^^^^^^^^^^^
  File "C:\python311\Lib\site-packages\MySQLdb\cursors.py", line 319, in _query
    db.query(q)
  File "C:\python311\Lib\site-packages\MySQLdb\connections.py", line 254, in query
    _mysql.connection.query(self, query)
MySQLdb.OperationalError: (1054, "Unknown column 'user_name' in 'field list'")

The above exception was the direct cause of the following exception:

Traceback (most recent call last):
  File "C:\python311\Lib\site-packages\django\core\handlers\exception.py", line 55, in inner
    response = get_response(request)
               ^^^^^^^^^^^^^^^^^^^^^
  File "C:\python311\Lib\site-packages\django\core\handlers\base.py", line 197, in _get_response
    response = wrapped_callback(request, *callback_args, **callback_kwargs)
               ^^^^^^^^^^^^^^^^^^^^^^^^^^^^^^^^^^^^^^^^^^^^^^^^^^^^^^^^^^^^
  File "D:\Coding\Projects\designcrafter\designcrafter\designcrafter\views.py", line 41, in sendotp
    user1.save()
  File "C:\python311\Lib\site-packages\django\db\models\base.py", line 814, in save
    self.save_base(
  File "C:\python311\Lib\site-packages\django\db\models\base.py", line 877, in save_base
    updated = self._save_table(
              ^^^^^^^^^^^^^^^^^
  File "C:\python311\Lib\site-packages\django\db\models\base.py", line 1020, in _save_table
    results = self._do_insert(
              ^^^^^^^^^^^^^^^^
  File "C:\python311\Lib\site-packages\django\db\models\base.py", line 1061, in _do_insert
    return manager._insert(
           ^^^^^^^^^^^^^^^^
  File "C:\python311\Lib\site-packages\django\db\models\manager.py", line 87, in manager_method
    return getattr(self.get_queryset(), name)(*args, **kwargs)
           ^^^^^^^^^^^^^^^^^^^^^^^^^^^^^^^^^^^^^^^^^^^^^^^^^^^
  File "C:\python311\Lib\site-packages\django\db\models\query.py", line 1805, in _insert
    return query.get_compiler(using=using).execute_sql(returning_fields)
           ^^^^^^^^^^^^^^^^^^^^^^^^^^^^^^^^^^^^^^^^^^^^^^^^^^^^^^^^^^^^^
  File "C:\python311\Lib\site-packages\django\db\models\sql\compiler.py", line 1822, in execute_sql
    cursor.execute(sql, params)
  File "C:\python311\Lib\site-packages\django\db\backends\utils.py", line 102, in execute
    return super().execute(sql, params)
           ^^^^^^^^^^^^^^^^^^^^^^^^^^^^
  File "C:\python311\Lib\site-packages\django\db\backends\utils.py", line 67, in execute
    return self._execute_with_wrappers(
           ^^^^^^^^^^^^^^^^^^^^^^^^^^^^
  File "C:\python311\Lib\site-packages\django\db\backends\utils.py", line 80, in _execute_with_wrappers
    return executor(sql, params, many, context)
           ^^^^^^^^^^^^^^^^^^^^^^^^^^^^^^^^^^^^
  File "C:\python311\Lib\site-packages\django\db\backends\utils.py", line 84, in _execute
    with self.db.wrap_database_errors:
  File "C:\python311\Lib\site-packages\django\db\utils.py", line 91, in __exit__
    raise dj_exc_value.with_traceback(traceback) from exc_value
  File "C:\python311\Lib\site-packages\django\db\backends\utils.py", line 89, in _execute
    return self.cursor.execute(sql, params)
           ^^^^^^^^^^^^^^^^^^^^^^^^^^^^^^^^
  File "C:\python311\Lib\site-packages\django\db\backends\mysql\base.py", line 75, in execute
    return self.cursor.execute(query, args)
           ^^^^^^^^^^^^^^^^^^^^^^^^^^^^^^^^
  File "C:\python311\Lib\site-packages\MySQLdb\cursors.py", line 206, in execute
    res = self._query(query)
          ^^^^^^^^^^^^^^^^^^
  File "C:\python311\Lib\site-packages\MySQLdb\cursors.py", line 319, in _query
    db.query(q)
  File "C:\python311\Lib\site-packages\MySQLdb\connections.py", line 254, in query
    _mysql.connection.query(self, query)
django.db.utils.OperationalError: (1054, "Unknown column 'user_name' in 'field list'")
2023-10-05 11:18:31,450 - ERROR - Internal Server Error: /sendotp
Traceback (most recent call last):
  File "C:\python311\Lib\site-packages\django\db\backends\utils.py", line 89, in _execute
    return self.cursor.execute(sql, params)
           ^^^^^^^^^^^^^^^^^^^^^^^^^^^^^^^^
  File "C:\python311\Lib\site-packages\django\db\backends\mysql\base.py", line 75, in execute
    return self.cursor.execute(query, args)
           ^^^^^^^^^^^^^^^^^^^^^^^^^^^^^^^^
  File "C:\python311\Lib\site-packages\MySQLdb\cursors.py", line 206, in execute
    res = self._query(query)
          ^^^^^^^^^^^^^^^^^^
  File "C:\python311\Lib\site-packages\MySQLdb\cursors.py", line 319, in _query
    db.query(q)
  File "C:\python311\Lib\site-packages\MySQLdb\connections.py", line 254, in query
    _mysql.connection.query(self, query)
MySQLdb.OperationalError: (1054, "Unknown column 'dc_user_data.user_name' in 'field list'")

The above exception was the direct cause of the following exception:

Traceback (most recent call last):
  File "D:\Coding\Projects\designcrafter\designcrafter\designcrafter\views.py", line 27, in sendotp
    username1 = Newuser.objects.get(user_name=user_names)
                ^^^^^^^^^^^^^^^^^^^^^^^^^^^^^^^^^^^^^^^^^
  File "C:\python311\Lib\site-packages\django\db\models\manager.py", line 87, in manager_method
    return getattr(self.get_queryset(), name)(*args, **kwargs)
           ^^^^^^^^^^^^^^^^^^^^^^^^^^^^^^^^^^^^^^^^^^^^^^^^^^^
  File "C:\python311\Lib\site-packages\django\db\models\query.py", line 633, in get
    num = len(clone)
          ^^^^^^^^^^
  File "C:\python311\Lib\site-packages\django\db\models\query.py", line 380, in __len__
    self._fetch_all()
  File "C:\python311\Lib\site-packages\django\db\models\query.py", line 1881, in _fetch_all
    self._result_cache = list(self._iterable_class(self))
                         ^^^^^^^^^^^^^^^^^^^^^^^^^^^^^^^^
  File "C:\python311\Lib\site-packages\django\db\models\query.py", line 91, in __iter__
    results = compiler.execute_sql(
              ^^^^^^^^^^^^^^^^^^^^^
  File "C:\python311\Lib\site-packages\django\db\models\sql\compiler.py", line 1562, in execute_sql
    cursor.execute(sql, params)
  File "C:\python311\Lib\site-packages\django\db\backends\utils.py", line 102, in execute
    return super().execute(sql, params)
           ^^^^^^^^^^^^^^^^^^^^^^^^^^^^
  File "C:\python311\Lib\site-packages\django\db\backends\utils.py", line 67, in execute
    return self._execute_with_wrappers(
           ^^^^^^^^^^^^^^^^^^^^^^^^^^^^
  File "C:\python311\Lib\site-packages\django\db\backends\utils.py", line 80, in _execute_with_wrappers
    return executor(sql, params, many, context)
           ^^^^^^^^^^^^^^^^^^^^^^^^^^^^^^^^^^^^
  File "C:\python311\Lib\site-packages\django\db\backends\utils.py", line 84, in _execute
    with self.db.wrap_database_errors:
  File "C:\python311\Lib\site-packages\django\db\utils.py", line 91, in __exit__
    raise dj_exc_value.with_traceback(traceback) from exc_value
  File "C:\python311\Lib\site-packages\django\db\backends\utils.py", line 89, in _execute
    return self.cursor.execute(sql, params)
           ^^^^^^^^^^^^^^^^^^^^^^^^^^^^^^^^
  File "C:\python311\Lib\site-packages\django\db\backends\mysql\base.py", line 75, in execute
    return self.cursor.execute(query, args)
           ^^^^^^^^^^^^^^^^^^^^^^^^^^^^^^^^
  File "C:\python311\Lib\site-packages\MySQLdb\cursors.py", line 206, in execute
    res = self._query(query)
          ^^^^^^^^^^^^^^^^^^
  File "C:\python311\Lib\site-packages\MySQLdb\cursors.py", line 319, in _query
    db.query(q)
  File "C:\python311\Lib\site-packages\MySQLdb\connections.py", line 254, in query
    _mysql.connection.query(self, query)
django.db.utils.OperationalError: (1054, "Unknown column 'dc_user_data.user_name' in 'field list'")

During handling of the above exception, another exception occurred:

Traceback (most recent call last):
  File "C:\python311\Lib\site-packages\django\db\backends\utils.py", line 89, in _execute
    return self.cursor.execute(sql, params)
           ^^^^^^^^^^^^^^^^^^^^^^^^^^^^^^^^
  File "C:\python311\Lib\site-packages\django\db\backends\mysql\base.py", line 75, in execute
    return self.cursor.execute(query, args)
           ^^^^^^^^^^^^^^^^^^^^^^^^^^^^^^^^
  File "C:\python311\Lib\site-packages\MySQLdb\cursors.py", line 206, in execute
    res = self._query(query)
          ^^^^^^^^^^^^^^^^^^
  File "C:\python311\Lib\site-packages\MySQLdb\cursors.py", line 319, in _query
    db.query(q)
  File "C:\python311\Lib\site-packages\MySQLdb\connections.py", line 254, in query
    _mysql.connection.query(self, query)
MySQLdb.OperationalError: (1054, "Unknown column 'user_name' in 'field list'")

The above exception was the direct cause of the following exception:

Traceback (most recent call last):
  File "C:\python311\Lib\site-packages\django\core\handlers\exception.py", line 55, in inner
    response = get_response(request)
               ^^^^^^^^^^^^^^^^^^^^^
  File "C:\python311\Lib\site-packages\django\core\handlers\base.py", line 197, in _get_response
    response = wrapped_callback(request, *callback_args, **callback_kwargs)
               ^^^^^^^^^^^^^^^^^^^^^^^^^^^^^^^^^^^^^^^^^^^^^^^^^^^^^^^^^^^^
  File "D:\Coding\Projects\designcrafter\designcrafter\designcrafter\views.py", line 41, in sendotp
    user1.save()
  File "C:\python311\Lib\site-packages\django\db\models\base.py", line 814, in save
    self.save_base(
  File "C:\python311\Lib\site-packages\django\db\models\base.py", line 877, in save_base
    updated = self._save_table(
              ^^^^^^^^^^^^^^^^^
  File "C:\python311\Lib\site-packages\django\db\models\base.py", line 1020, in _save_table
    results = self._do_insert(
              ^^^^^^^^^^^^^^^^
  File "C:\python311\Lib\site-packages\django\db\models\base.py", line 1061, in _do_insert
    return manager._insert(
           ^^^^^^^^^^^^^^^^
  File "C:\python311\Lib\site-packages\django\db\models\manager.py", line 87, in manager_method
    return getattr(self.get_queryset(), name)(*args, **kwargs)
           ^^^^^^^^^^^^^^^^^^^^^^^^^^^^^^^^^^^^^^^^^^^^^^^^^^^
  File "C:\python311\Lib\site-packages\django\db\models\query.py", line 1805, in _insert
    return query.get_compiler(using=using).execute_sql(returning_fields)
           ^^^^^^^^^^^^^^^^^^^^^^^^^^^^^^^^^^^^^^^^^^^^^^^^^^^^^^^^^^^^^
  File "C:\python311\Lib\site-packages\django\db\models\sql\compiler.py", line 1822, in execute_sql
    cursor.execute(sql, params)
  File "C:\python311\Lib\site-packages\django\db\backends\utils.py", line 102, in execute
    return super().execute(sql, params)
           ^^^^^^^^^^^^^^^^^^^^^^^^^^^^
  File "C:\python311\Lib\site-packages\django\db\backends\utils.py", line 67, in execute
    return self._execute_with_wrappers(
           ^^^^^^^^^^^^^^^^^^^^^^^^^^^^
  File "C:\python311\Lib\site-packages\django\db\backends\utils.py", line 80, in _execute_with_wrappers
    return executor(sql, params, many, context)
           ^^^^^^^^^^^^^^^^^^^^^^^^^^^^^^^^^^^^
  File "C:\python311\Lib\site-packages\django\db\backends\utils.py", line 84, in _execute
    with self.db.wrap_database_errors:
  File "C:\python311\Lib\site-packages\django\db\utils.py", line 91, in __exit__
    raise dj_exc_value.with_traceback(traceback) from exc_value
  File "C:\python311\Lib\site-packages\django\db\backends\utils.py", line 89, in _execute
    return self.cursor.execute(sql, params)
           ^^^^^^^^^^^^^^^^^^^^^^^^^^^^^^^^
  File "C:\python311\Lib\site-packages\django\db\backends\mysql\base.py", line 75, in execute
    return self.cursor.execute(query, args)
           ^^^^^^^^^^^^^^^^^^^^^^^^^^^^^^^^
  File "C:\python311\Lib\site-packages\MySQLdb\cursors.py", line 206, in execute
    res = self._query(query)
          ^^^^^^^^^^^^^^^^^^
  File "C:\python311\Lib\site-packages\MySQLdb\cursors.py", line 319, in _query
    db.query(q)
  File "C:\python311\Lib\site-packages\MySQLdb\connections.py", line 254, in query
    _mysql.connection.query(self, query)
django.db.utils.OperationalError: (1054, "Unknown column 'user_name' in 'field list'")
2023-10-05 11:18:43,242 - INFO - D:\Coding\Projects\designcrafter\designcrafter\designcrafter\views.py changed, reloading.
2023-10-05 11:18:47,287 - ERROR - Internal Server Error: /sendotp
Traceback (most recent call last):
  File "C:\python311\Lib\site-packages\django\db\backends\utils.py", line 89, in _execute
    return self.cursor.execute(sql, params)
           ^^^^^^^^^^^^^^^^^^^^^^^^^^^^^^^^
  File "C:\python311\Lib\site-packages\django\db\backends\mysql\base.py", line 75, in execute
    return self.cursor.execute(query, args)
           ^^^^^^^^^^^^^^^^^^^^^^^^^^^^^^^^
  File "C:\python311\Lib\site-packages\MySQLdb\cursors.py", line 206, in execute
    res = self._query(query)
          ^^^^^^^^^^^^^^^^^^
  File "C:\python311\Lib\site-packages\MySQLdb\cursors.py", line 319, in _query
    db.query(q)
  File "C:\python311\Lib\site-packages\MySQLdb\connections.py", line 254, in query
    _mysql.connection.query(self, query)
MySQLdb.OperationalError: (1054, "Unknown column 'dc_user_data.user_name' in 'field list'")

The above exception was the direct cause of the following exception:

Traceback (most recent call last):
  File "D:\Coding\Projects\designcrafter\designcrafter\designcrafter\views.py", line 27, in sendotp
    username1 = Newuser.objects.get(user_name=user_names)
                ^^^^^^^^^^^^^^^^^^^^^^^^^^^^^^^^^^^^^^^^^
  File "C:\python311\Lib\site-packages\django\db\models\manager.py", line 87, in manager_method
    return getattr(self.get_queryset(), name)(*args, **kwargs)
           ^^^^^^^^^^^^^^^^^^^^^^^^^^^^^^^^^^^^^^^^^^^^^^^^^^^
  File "C:\python311\Lib\site-packages\django\db\models\query.py", line 633, in get
    num = len(clone)
          ^^^^^^^^^^
  File "C:\python311\Lib\site-packages\django\db\models\query.py", line 380, in __len__
    self._fetch_all()
  File "C:\python311\Lib\site-packages\django\db\models\query.py", line 1881, in _fetch_all
    self._result_cache = list(self._iterable_class(self))
                         ^^^^^^^^^^^^^^^^^^^^^^^^^^^^^^^^
  File "C:\python311\Lib\site-packages\django\db\models\query.py", line 91, in __iter__
    results = compiler.execute_sql(
              ^^^^^^^^^^^^^^^^^^^^^
  File "C:\python311\Lib\site-packages\django\db\models\sql\compiler.py", line 1562, in execute_sql
    cursor.execute(sql, params)
  File "C:\python311\Lib\site-packages\django\db\backends\utils.py", line 102, in execute
    return super().execute(sql, params)
           ^^^^^^^^^^^^^^^^^^^^^^^^^^^^
  File "C:\python311\Lib\site-packages\django\db\backends\utils.py", line 67, in execute
    return self._execute_with_wrappers(
           ^^^^^^^^^^^^^^^^^^^^^^^^^^^^
  File "C:\python311\Lib\site-packages\django\db\backends\utils.py", line 80, in _execute_with_wrappers
    return executor(sql, params, many, context)
           ^^^^^^^^^^^^^^^^^^^^^^^^^^^^^^^^^^^^
  File "C:\python311\Lib\site-packages\django\db\backends\utils.py", line 84, in _execute
    with self.db.wrap_database_errors:
  File "C:\python311\Lib\site-packages\django\db\utils.py", line 91, in __exit__
    raise dj_exc_value.with_traceback(traceback) from exc_value
  File "C:\python311\Lib\site-packages\django\db\backends\utils.py", line 89, in _execute
    return self.cursor.execute(sql, params)
           ^^^^^^^^^^^^^^^^^^^^^^^^^^^^^^^^
  File "C:\python311\Lib\site-packages\django\db\backends\mysql\base.py", line 75, in execute
    return self.cursor.execute(query, args)
           ^^^^^^^^^^^^^^^^^^^^^^^^^^^^^^^^
  File "C:\python311\Lib\site-packages\MySQLdb\cursors.py", line 206, in execute
    res = self._query(query)
          ^^^^^^^^^^^^^^^^^^
  File "C:\python311\Lib\site-packages\MySQLdb\cursors.py", line 319, in _query
    db.query(q)
  File "C:\python311\Lib\site-packages\MySQLdb\connections.py", line 254, in query
    _mysql.connection.query(self, query)
django.db.utils.OperationalError: (1054, "Unknown column 'dc_user_data.user_name' in 'field list'")

During handling of the above exception, another exception occurred:

Traceback (most recent call last):
  File "C:\python311\Lib\site-packages\django\db\backends\utils.py", line 89, in _execute
    return self.cursor.execute(sql, params)
           ^^^^^^^^^^^^^^^^^^^^^^^^^^^^^^^^
  File "C:\python311\Lib\site-packages\django\db\backends\mysql\base.py", line 75, in execute
    return self.cursor.execute(query, args)
           ^^^^^^^^^^^^^^^^^^^^^^^^^^^^^^^^
  File "C:\python311\Lib\site-packages\MySQLdb\cursors.py", line 206, in execute
    res = self._query(query)
          ^^^^^^^^^^^^^^^^^^
  File "C:\python311\Lib\site-packages\MySQLdb\cursors.py", line 319, in _query
    db.query(q)
  File "C:\python311\Lib\site-packages\MySQLdb\connections.py", line 254, in query
    _mysql.connection.query(self, query)
MySQLdb.OperationalError: (1054, "Unknown column 'user_name' in 'field list'")

The above exception was the direct cause of the following exception:

Traceback (most recent call last):
  File "C:\python311\Lib\site-packages\django\core\handlers\exception.py", line 55, in inner
    response = get_response(request)
               ^^^^^^^^^^^^^^^^^^^^^
  File "C:\python311\Lib\site-packages\django\core\handlers\base.py", line 197, in _get_response
    response = wrapped_callback(request, *callback_args, **callback_kwargs)
               ^^^^^^^^^^^^^^^^^^^^^^^^^^^^^^^^^^^^^^^^^^^^^^^^^^^^^^^^^^^^
  File "D:\Coding\Projects\designcrafter\designcrafter\designcrafter\views.py", line 41, in sendotp
    user1.save()
  File "C:\python311\Lib\site-packages\django\db\models\base.py", line 814, in save
    self.save_base(
  File "C:\python311\Lib\site-packages\django\db\models\base.py", line 877, in save_base
    updated = self._save_table(
              ^^^^^^^^^^^^^^^^^
  File "C:\python311\Lib\site-packages\django\db\models\base.py", line 1020, in _save_table
    results = self._do_insert(
              ^^^^^^^^^^^^^^^^
  File "C:\python311\Lib\site-packages\django\db\models\base.py", line 1061, in _do_insert
    return manager._insert(
           ^^^^^^^^^^^^^^^^
  File "C:\python311\Lib\site-packages\django\db\models\manager.py", line 87, in manager_method
    return getattr(self.get_queryset(), name)(*args, **kwargs)
           ^^^^^^^^^^^^^^^^^^^^^^^^^^^^^^^^^^^^^^^^^^^^^^^^^^^
  File "C:\python311\Lib\site-packages\django\db\models\query.py", line 1805, in _insert
    return query.get_compiler(using=using).execute_sql(returning_fields)
           ^^^^^^^^^^^^^^^^^^^^^^^^^^^^^^^^^^^^^^^^^^^^^^^^^^^^^^^^^^^^^
  File "C:\python311\Lib\site-packages\django\db\models\sql\compiler.py", line 1822, in execute_sql
    cursor.execute(sql, params)
  File "C:\python311\Lib\site-packages\django\db\backends\utils.py", line 102, in execute
    return super().execute(sql, params)
           ^^^^^^^^^^^^^^^^^^^^^^^^^^^^
  File "C:\python311\Lib\site-packages\django\db\backends\utils.py", line 67, in execute
    return self._execute_with_wrappers(
           ^^^^^^^^^^^^^^^^^^^^^^^^^^^^
  File "C:\python311\Lib\site-packages\django\db\backends\utils.py", line 80, in _execute_with_wrappers
    return executor(sql, params, many, context)
           ^^^^^^^^^^^^^^^^^^^^^^^^^^^^^^^^^^^^
  File "C:\python311\Lib\site-packages\django\db\backends\utils.py", line 84, in _execute
    with self.db.wrap_database_errors:
  File "C:\python311\Lib\site-packages\django\db\utils.py", line 91, in __exit__
    raise dj_exc_value.with_traceback(traceback) from exc_value
  File "C:\python311\Lib\site-packages\django\db\backends\utils.py", line 89, in _execute
    return self.cursor.execute(sql, params)
           ^^^^^^^^^^^^^^^^^^^^^^^^^^^^^^^^
  File "C:\python311\Lib\site-packages\django\db\backends\mysql\base.py", line 75, in execute
    return self.cursor.execute(query, args)
           ^^^^^^^^^^^^^^^^^^^^^^^^^^^^^^^^
  File "C:\python311\Lib\site-packages\MySQLdb\cursors.py", line 206, in execute
    res = self._query(query)
          ^^^^^^^^^^^^^^^^^^
  File "C:\python311\Lib\site-packages\MySQLdb\cursors.py", line 319, in _query
    db.query(q)
  File "C:\python311\Lib\site-packages\MySQLdb\connections.py", line 254, in query
    _mysql.connection.query(self, query)
django.db.utils.OperationalError: (1054, "Unknown column 'user_name' in 'field list'")
2023-10-05 11:19:41,919 - INFO - D:\Coding\Projects\designcrafter\designcrafter\designcrafter\views.py changed, reloading.
2023-10-05 11:20:46,587 - INFO - D:\Coding\Projects\designcrafter\designcrafter\designcrafter\views.py changed, reloading.
2023-10-06 09:17:10,290 - WARNING - Not Found: /
2023-10-06 09:17:10,475 - WARNING - Not Found: /favicon.ico
2023-10-06 09:21:25,471 - INFO - D:\Coding\Projects\designcrafter\designcrafter\designcrafter\views.py changed, reloading.
2023-10-06 09:21:48,147 - INFO - D:\Coding\Projects\designcrafter\designcrafter\designcrafter\models.py changed, reloading.
2023-10-06 09:24:07,012 - INFO - D:\Coding\Projects\designcrafter\designcrafter\designcrafter\views.py changed, reloading.
2023-10-06 09:24:21,307 - INFO - D:\Coding\Projects\designcrafter\designcrafter\designcrafter\views.py changed, reloading.
2023-10-06 09:24:33,504 - INFO - D:\Coding\Projects\designcrafter\designcrafter\designcrafter\views.py changed, reloading.
2023-10-06 09:25:00,081 - INFO - D:\Coding\Projects\designcrafter\designcrafter\designcrafter\views.py changed, reloading.
2023-10-06 09:25:53,412 - INFO - D:\Coding\Projects\designcrafter\designcrafter\designcrafter\views.py changed, reloading.
2023-10-06 09:27:07,673 - INFO - D:\Coding\Projects\designcrafter\designcrafter\designcrafter\views.py changed, reloading.
2023-10-06 09:30:52,058 - WARNING - Not Found: /
2023-10-06 10:28:04,992 - INFO - D:\Coding\Projects\designcrafter\designcrafter\designcrafter\views.py changed, reloading.
2023-10-06 10:30:11,272 - INFO - D:\Coding\Projects\designcrafter\designcrafter\designcrafter\views.py changed, reloading.
2023-10-06 10:33:31,438 - INFO - D:\Coding\Projects\designcrafter\designcrafter\designcrafter\views.py changed, reloading.
2023-10-06 10:33:39,557 - INFO - D:\Coding\Projects\designcrafter\designcrafter\designcrafter\views.py changed, reloading.
2023-10-06 10:34:57,512 - INFO - D:\Coding\Projects\designcrafter\designcrafter\designcrafter\views.py changed, reloading.
2023-10-06 10:35:09,851 - INFO - D:\Coding\Projects\designcrafter\designcrafter\designcrafter\views.py changed, reloading.
2023-10-06 10:35:42,646 - INFO - D:\Coding\Projects\designcrafter\designcrafter\designcrafter\views.py changed, reloading.
2023-10-06 10:36:08,969 - INFO - D:\Coding\Projects\designcrafter\designcrafter\designcrafter\views.py changed, reloading.
2023-10-06 10:39:25,082 - INFO - D:\Coding\Projects\designcrafter\designcrafter\designcrafter\views.py changed, reloading.
2023-10-06 10:39:49,702 - INFO - D:\Coding\Projects\designcrafter\designcrafter\designcrafter\urls.py changed, reloading.
2023-10-06 10:39:51,637 - INFO - D:\Coding\Projects\designcrafter\designcrafter\designcrafter\urls.py changed, reloading.
2023-10-06 10:40:56,203 - INFO - D:\Coding\Projects\designcrafter\designcrafter\designcrafter\views.py changed, reloading.
2023-10-06 10:41:39,248 - INFO - D:\Coding\Projects\designcrafter\designcrafter\designcrafter\views.py changed, reloading.
2023-10-06 10:41:55,582 - INFO - D:\Coding\Projects\designcrafter\designcrafter\designcrafter\views.py changed, reloading.
2023-10-06 10:43:25,807 - INFO - D:\Coding\Projects\designcrafter\designcrafter\designcrafter\views.py changed, reloading.
2023-10-06 10:43:48,260 - INFO - D:\Coding\Projects\designcrafter\designcrafter\designcrafter\views.py changed, reloading.
2023-10-06 10:44:01,469 - INFO - D:\Coding\Projects\designcrafter\designcrafter\designcrafter\views.py changed, reloading.
2023-10-06 10:47:00,972 - INFO - D:\Coding\Projects\designcrafter\designcrafter\designcrafter\views.py changed, reloading.
2023-10-06 10:47:41,969 - INFO - D:\Coding\Projects\designcrafter\designcrafter\designcrafter\views.py changed, reloading.
2023-10-06 10:48:01,943 - ERROR - Internal Server Error: /sendotp
Traceback (most recent call last):
  File "D:\Coding\Projects\designcrafter\designcrafter\designcrafter\views.py", line 30, in sendotp
    username1 = Newuser.objects.get( user_email = user_emails)
                ^^^^^^^^^^^^^^^^^^^^^^^^^^^^^^^^^^^^^^^^^^^^^^
  File "C:\python311\Lib\site-packages\django\db\models\manager.py", line 87, in manager_method
    return getattr(self.get_queryset(), name)(*args, **kwargs)
           ^^^^^^^^^^^^^^^^^^^^^^^^^^^^^^^^^^^^^^^^^^^^^^^^^^^
  File "C:\python311\Lib\site-packages\django\db\models\query.py", line 637, in get
    raise self.model.DoesNotExist(
designcrafter.models.Newuser.DoesNotExist: Newuser matching query does not exist.

During handling of the above exception, another exception occurred:

Traceback (most recent call last):
  File "C:\python311\Lib\site-packages\django\core\handlers\exception.py", line 55, in inner
    response = get_response(request)
               ^^^^^^^^^^^^^^^^^^^^^
  File "C:\python311\Lib\site-packages\django\core\handlers\base.py", line 197, in _get_response
    response = wrapped_callback(request, *callback_args, **callback_kwargs)
               ^^^^^^^^^^^^^^^^^^^^^^^^^^^^^^^^^^^^^^^^^^^^^^^^^^^^^^^^^^^^
  File "D:\Coding\Projects\designcrafter\designcrafter\designcrafter\views.py", line 43, in sendotp
    user1 = Newuser(user_name=user_names, user_email=user_emails, user_otp=otp,user_password = user_passwords)
            ^^^^^^^^^^^^^^^^^^^^^^^^^^^^^^^^^^^^^^^^^^^^^^^^^^^^^^^^^^^^^^^^^^^^^^^^^^^^^^^^^^^^^^^^^^^^^^^^^^
  File "C:\python311\Lib\site-packages\django\db\models\base.py", line 567, in __init__
    raise TypeError(
TypeError: Newuser() got unexpected keyword arguments: 'user_password'
2023-10-06 10:48:23,351 - INFO - D:\Coding\Projects\designcrafter\designcrafter\designcrafter\views.py changed, reloading.
2023-10-06 10:48:58,161 - INFO - D:\Coding\Projects\designcrafter\designcrafter\designcrafter\models.py changed, reloading.
2023-10-06 10:49:31,926 - WARNING - Not Found: /
2023-10-06 10:50:44,121 - INFO - D:\Coding\Projects\designcrafter\designcrafter\designcrafter\urls.py changed, reloading.
2023-10-06 10:52:51,366 - INFO - D:\Coding\Projects\designcrafter\designcrafter\designcrafter\views.py changed, reloading.
2023-10-06 10:55:03,808 - WARNING - Not Found: /
2023-10-06 10:55:11,246 - ERROR - Internal Server Error: /userlogin
Traceback (most recent call last):
  File "C:\python311\Lib\site-packages\django\core\handlers\exception.py", line 55, in inner
    response = get_response(request)
               ^^^^^^^^^^^^^^^^^^^^^
  File "C:\python311\Lib\site-packages\django\core\handlers\base.py", line 197, in _get_response
    response = wrapped_callback(request, *callback_args, **callback_kwargs)
               ^^^^^^^^^^^^^^^^^^^^^^^^^^^^^^^^^^^^^^^^^^^^^^^^^^^^^^^^^^^^
  File "D:\Coding\Projects\designcrafter\designcrafter\designcrafter\views.py", line 117, in userlogin
    return render (request,'login/userlogin1')
           ^^^^^^^^^^^^^^^^^^^^^^^^^^^^^^^^^^^
  File "C:\python311\Lib\site-packages\django\shortcuts.py", line 24, in render
    content = loader.render_to_string(template_name, context, request, using=using)
              ^^^^^^^^^^^^^^^^^^^^^^^^^^^^^^^^^^^^^^^^^^^^^^^^^^^^^^^^^^^^^^^^^^^^^
  File "C:\python311\Lib\site-packages\django\template\loader.py", line 61, in render_to_string
    template = get_template(template_name, using=using)
               ^^^^^^^^^^^^^^^^^^^^^^^^^^^^^^^^^^^^^^^^
  File "C:\python311\Lib\site-packages\django\template\loader.py", line 19, in get_template
    raise TemplateDoesNotExist(template_name, chain=chain)
django.template.exceptions.TemplateDoesNotExist: login/userlogin1
2023-10-06 10:55:27,645 - INFO - D:\Coding\Projects\designcrafter\designcrafter\designcrafter\views.py changed, reloading.
2023-10-06 10:56:07,907 - ERROR - Internal Server Error: /userlogin
Traceback (most recent call last):
  File "C:\python311\Lib\site-packages\django\core\handlers\exception.py", line 55, in inner
    response = get_response(request)
               ^^^^^^^^^^^^^^^^^^^^^
  File "C:\python311\Lib\site-packages\django\core\handlers\base.py", line 197, in _get_response
    response = wrapped_callback(request, *callback_args, **callback_kwargs)
               ^^^^^^^^^^^^^^^^^^^^^^^^^^^^^^^^^^^^^^^^^^^^^^^^^^^^^^^^^^^^
  File "D:\Coding\Projects\designcrafter\designcrafter\designcrafter\views.py", line 110, in userlogin
    if user.user_password==ps:
       ^^^^^^^^^^^^^^^^^^
AttributeError: 'Newuser' object has no attribute 'user_password'
2023-10-06 10:56:23,214 - INFO - D:\Coding\Projects\designcrafter\designcrafter\designcrafter\models.py changed, reloading.
2023-10-06 10:56:37,498 - INFO - D:\Coding\Projects\designcrafter\designcrafter\designcrafter\views.py changed, reloading.
2023-10-06 10:59:33,302 - INFO - D:\Coding\Projects\designcrafter\designcrafter\designcrafter\views.py changed, reloading.
2023-10-06 11:02:42,256 - INFO - D:\Coding\Projects\designcrafter\designcrafter\designcrafter\views.py changed, reloading.
2023-10-06 11:03:34,541 - INFO - D:\Coding\Projects\designcrafter\designcrafter\designcrafter\views.py changed, reloading.
2023-10-06 11:03:43,684 - INFO - D:\Coding\Projects\designcrafter\designcrafter\designcrafter\views.py changed, reloading.
2023-10-06 11:03:49,241 - ERROR - Internal Server Error: /userlogin
Traceback (most recent call last):
  File "C:\python311\Lib\site-packages\django\core\handlers\exception.py", line 55, in inner
    response = get_response(request)
               ^^^^^^^^^^^^^^^^^^^^^
  File "C:\python311\Lib\site-packages\django\core\handlers\base.py", line 197, in _get_response
    response = wrapped_callback(request, *callback_args, **callback_kwargs)
               ^^^^^^^^^^^^^^^^^^^^^^^^^^^^^^^^^^^^^^^^^^^^^^^^^^^^^^^^^^^^
  File "D:\Coding\Projects\designcrafter\designcrafter\designcrafter\views.py", line 123, in userlogin
    return redirect ('user_session')
           ^^^^^^^^^^^^^^^^^^^^^^^^^
  File "C:\python311\Lib\site-packages\django\shortcuts.py", line 48, in redirect
    return redirect_class(resolve_url(to, *args, **kwargs))
                          ^^^^^^^^^^^^^^^^^^^^^^^^^^^^^^^^
  File "C:\python311\Lib\site-packages\django\shortcuts.py", line 145, in resolve_url
    return reverse(to, args=args, kwargs=kwargs)
           ^^^^^^^^^^^^^^^^^^^^^^^^^^^^^^^^^^^^^
  File "C:\python311\Lib\site-packages\django\urls\base.py", line 88, in reverse
    return resolver._reverse_with_prefix(view, prefix, *args, **kwargs)
           ^^^^^^^^^^^^^^^^^^^^^^^^^^^^^^^^^^^^^^^^^^^^^^^^^^^^^^^^^^^^
  File "C:\python311\Lib\site-packages\django\urls\resolvers.py", line 828, in _reverse_with_prefix
    raise NoReverseMatch(msg)
django.urls.exceptions.NoReverseMatch: Reverse for 'user_session' not found. 'user_session' is not a valid view function or pattern name.
2023-10-06 11:03:50,632 - ERROR - Internal Server Error: /userlogin
Traceback (most recent call last):
  File "C:\python311\Lib\site-packages\django\core\handlers\exception.py", line 55, in inner
    response = get_response(request)
               ^^^^^^^^^^^^^^^^^^^^^
  File "C:\python311\Lib\site-packages\django\core\handlers\base.py", line 197, in _get_response
    response = wrapped_callback(request, *callback_args, **callback_kwargs)
               ^^^^^^^^^^^^^^^^^^^^^^^^^^^^^^^^^^^^^^^^^^^^^^^^^^^^^^^^^^^^
  File "D:\Coding\Projects\designcrafter\designcrafter\designcrafter\views.py", line 123, in userlogin
    return redirect ('user_session')
           ^^^^^^^^^^^^^^^^^^^^^^^^^
  File "C:\python311\Lib\site-packages\django\shortcuts.py", line 48, in redirect
    return redirect_class(resolve_url(to, *args, **kwargs))
                          ^^^^^^^^^^^^^^^^^^^^^^^^^^^^^^^^
  File "C:\python311\Lib\site-packages\django\shortcuts.py", line 145, in resolve_url
    return reverse(to, args=args, kwargs=kwargs)
           ^^^^^^^^^^^^^^^^^^^^^^^^^^^^^^^^^^^^^
  File "C:\python311\Lib\site-packages\django\urls\base.py", line 88, in reverse
    return resolver._reverse_with_prefix(view, prefix, *args, **kwargs)
           ^^^^^^^^^^^^^^^^^^^^^^^^^^^^^^^^^^^^^^^^^^^^^^^^^^^^^^^^^^^^
  File "C:\python311\Lib\site-packages\django\urls\resolvers.py", line 828, in _reverse_with_prefix
    raise NoReverseMatch(msg)
django.urls.exceptions.NoReverseMatch: Reverse for 'user_session' not found. 'user_session' is not a valid view function or pattern name.
2023-10-06 11:04:02,273 - INFO - D:\Coding\Projects\designcrafter\designcrafter\designcrafter\views.py changed, reloading.
2023-10-06 11:04:06,608 - ERROR - Internal Server Error: /userlogin
Traceback (most recent call last):
  File "C:\python311\Lib\site-packages\django\core\handlers\exception.py", line 55, in inner
    response = get_response(request)
               ^^^^^^^^^^^^^^^^^^^^^
  File "C:\python311\Lib\site-packages\django\core\handlers\base.py", line 197, in _get_response
    response = wrapped_callback(request, *callback_args, **callback_kwargs)
               ^^^^^^^^^^^^^^^^^^^^^^^^^^^^^^^^^^^^^^^^^^^^^^^^^^^^^^^^^^^^
  File "D:\Coding\Projects\designcrafter\designcrafter\designcrafter\views.py", line 123, in userlogin
    return redirect ('user_session')
           ^^^^^^^^^^^^^^^^^^^^^^^^^
  File "C:\python311\Lib\site-packages\django\shortcuts.py", line 48, in redirect
    return redirect_class(resolve_url(to, *args, **kwargs))
                          ^^^^^^^^^^^^^^^^^^^^^^^^^^^^^^^^
  File "C:\python311\Lib\site-packages\django\shortcuts.py", line 145, in resolve_url
    return reverse(to, args=args, kwargs=kwargs)
           ^^^^^^^^^^^^^^^^^^^^^^^^^^^^^^^^^^^^^
  File "C:\python311\Lib\site-packages\django\urls\base.py", line 88, in reverse
    return resolver._reverse_with_prefix(view, prefix, *args, **kwargs)
           ^^^^^^^^^^^^^^^^^^^^^^^^^^^^^^^^^^^^^^^^^^^^^^^^^^^^^^^^^^^^
  File "C:\python311\Lib\site-packages\django\urls\resolvers.py", line 828, in _reverse_with_prefix
    raise NoReverseMatch(msg)
django.urls.exceptions.NoReverseMatch: Reverse for 'user_session' not found. 'user_session' is not a valid view function or pattern name.
2023-10-06 11:04:36,426 - INFO - D:\Coding\Projects\designcrafter\designcrafter\designcrafter\views.py changed, reloading.
2023-10-06 11:05:34,881 - INFO - D:\Coding\Projects\designcrafter\designcrafter\designcrafter\views.py changed, reloading.
2023-10-06 11:05:36,853 - INFO - D:\Coding\Projects\designcrafter\designcrafter\designcrafter\views.py changed, reloading.
2023-10-06 11:06:37,357 - INFO - D:\Coding\Projects\designcrafter\designcrafter\designcrafter\urls.py changed, reloading.
2023-10-06 11:06:43,512 - WARNING - Not Found: /
2023-10-06 11:07:32,116 - INFO - D:\Coding\Projects\designcrafter\designcrafter\designcrafter\views.py changed, reloading.
2023-10-06 11:07:33,119 - ERROR - Internal Server Error: /userlogin
Traceback (most recent call last):
  File "C:\python311\Lib\site-packages\django\core\handlers\exception.py", line 55, in inner
    response = get_response(request)
               ^^^^^^^^^^^^^^^^^^^^^
  File "C:\python311\Lib\site-packages\django\core\handlers\base.py", line 197, in _get_response
    response = wrapped_callback(request, *callback_args, **callback_kwargs)
               ^^^^^^^^^^^^^^^^^^^^^^^^^^^^^^^^^^^^^^^^^^^^^^^^^^^^^^^^^^^^
  File "D:\Coding\Projects\designcrafter\designcrafter\designcrafter\views.py", line 110, in userlogin
    user_id = user_id.id
              ^^^^^^^
UnboundLocalError: cannot access local variable 'user_id' where it is not associated with a value
2023-10-06 11:08:22,410 - INFO - D:\Coding\Projects\designcrafter\designcrafter\designcrafter\views.py changed, reloading.
2023-10-06 11:10:07,195 - INFO - D:\Coding\Projects\designcrafter\designcrafter\designcrafter\views.py changed, reloading.
2023-10-06 11:11:06,712 - INFO - D:\Coding\Projects\designcrafter\designcrafter\designcrafter\views.py changed, reloading.
2023-10-06 11:22:54,727 - INFO - D:\Coding\Projects\designcrafter\designcrafter\designcrafter\views.py changed, reloading.
2023-10-06 11:27:08,009 - ERROR - Internal Server Error: /userlogin
Traceback (most recent call last):
  File "C:\python311\Lib\site-packages\django\core\handlers\exception.py", line 55, in inner
    response = get_response(request)
               ^^^^^^^^^^^^^^^^^^^^^
  File "C:\python311\Lib\site-packages\django\core\handlers\base.py", line 197, in _get_response
    response = wrapped_callback(request, *callback_args, **callback_kwargs)
               ^^^^^^^^^^^^^^^^^^^^^^^^^^^^^^^^^^^^^^^^^^^^^^^^^^^^^^^^^^^^
  File "D:\Coding\Projects\designcrafter\designcrafter\designcrafter\views.py", line 109, in userlogin
    user = Newuser.objects.get(user_email=us)
           ^^^^^^^^^^^^^^^^^^^^^^^^^^^^^^^^^^
  File "C:\python311\Lib\site-packages\django\db\models\manager.py", line 87, in manager_method
    return getattr(self.get_queryset(), name)(*args, **kwargs)
           ^^^^^^^^^^^^^^^^^^^^^^^^^^^^^^^^^^^^^^^^^^^^^^^^^^^
  File "C:\python311\Lib\site-packages\django\db\models\query.py", line 640, in get
    raise self.model.MultipleObjectsReturned(
designcrafter.models.Newuser.MultipleObjectsReturned: get() returned more than one Newuser -- it returned 2!
2023-10-11 09:54:33,916 - INFO - D:\Coding\Projects\designcrafter\designcrafter\designcrafter\views.py changed, reloading.
2023-10-11 09:54:54,684 - INFO - D:\Coding\Projects\designcrafter\designcrafter\designcrafter\urls.py changed, reloading.
2023-10-11 09:55:02,299 - WARNING - Not Found: /
2023-10-11 09:55:02,441 - WARNING - Not Found: /favicon.ico
2023-10-11 09:58:30,096 - WARNING - Not Found: /style.css
2023-10-11 09:58:30,097 - WARNING - Not Found: /<link rel=
2023-10-11 10:00:22,538 - WARNING - Not Found: /style.css
2023-10-11 10:00:22,540 - WARNING - Not Found: /<link rel=
2023-10-11 10:00:23,666 - WARNING - Not Found: /style.css
2023-10-11 10:00:23,667 - WARNING - Not Found: /<link rel=
2023-10-11 10:00:56,744 - WARNING - Not Found: /<link rel=
2023-10-11 10:00:56,746 - WARNING - Not Found: /style.css
2023-10-11 10:11:52,479 - WARNING - Not Found: /style.css
2023-10-11 10:11:52,481 - WARNING - Not Found: /<link rel=
2023-10-11 10:13:09,746 - WARNING - Not Found: /style.css
2023-10-11 10:13:21,663 - WARNING - Not Found: /style.css
2023-10-11 10:13:41,907 - WARNING - Not Found: /style.css
2023-10-11 10:22:27,481 - WARNING - Not Found: /style.css
2023-10-11 10:22:28,394 - WARNING - Not Found: /style.css
2023-10-11 10:54:15,604 - INFO - D:\Coding\Projects\designcrafter\designcrafter\designcrafter\settings.py changed, reloading.
2023-10-12 19:51:17,482 - WARNING - Not Found: /
2023-10-12 19:51:17,664 - WARNING - Not Found: /favicon.ico
2023-10-12 20:58:43,710 - INFO - D:\Coding\Projects\designcrafter\designcrafter\designcrafter\views.py changed, reloading.
2023-10-12 21:10:21,248 - INFO - D:\Coding\Projects\designcrafter\designcrafter\designcrafter\views.py changed, reloading.
2023-10-16 21:21:38,603 - WARNING - Not Found: /
2023-10-16 21:21:38,753 - WARNING - Not Found: /favicon.ico
2023-10-16 21:31:01,468 - INFO - D:\Coding\Projects\designcrafter\designcrafter\designcrafter\views.py changed, reloading.
2023-10-16 21:31:10,209 - WARNING - Not Found: /logo.jpg
2023-10-16 21:31:10,211 - WARNING - Not Found: /style.css
2023-10-16 21:32:04,305 - WARNING - Not Found: /logo.jpg
2023-10-16 21:32:37,900 - WARNING - Not Found: /logo.jpg
2023-10-16 21:32:53,872 - WARNING - Not Found: /logo.jpg
2023-10-16 21:32:54,988 - WARNING - Not Found: /logo.jpg
2023-10-16 21:32:56,683 - WARNING - Not Found: /logo.jpg
2023-10-16 21:33:05,571 - WARNING - Not Found: /logo.jpg
2023-10-16 21:34:07,383 - WARNING - Not Found: /logo.jpg
2023-10-16 21:34:24,564 - WARNING - Not Found: /logo.jpg
2023-10-16 21:35:21,817 - WARNING - Not Found: /logo.jpg
2023-10-16 21:35:24,183 - WARNING - Not Found: /logo.jpg
2023-10-16 21:36:20,989 - WARNING - Not Found: /logo.jpg
2023-10-16 21:36:40,425 - WARNING - Not Found: /logo.jpg
2023-10-16 21:37:10,530 - WARNING - Not Found: /logo.jpg
2023-10-16 21:38:35,880 - WARNING - Not Found: /logo.jpg
2023-10-16 21:40:24,484 - WARNING - Not Found: /logo.jpg
2023-10-16 21:40:33,390 - WARNING - Not Found: /logo.jpg
2023-10-16 21:41:12,093 - WARNING - Not Found: /logo.jpg
2023-10-16 21:41:13,503 - WARNING - Not Found: /logo.jpg
2023-10-16 21:41:37,003 - WARNING - Not Found: /logo.jpg
2023-10-16 21:41:59,029 - WARNING - Not Found: /logo.jpg
2023-10-17 09:21:40,627 - WARNING - Not Found: /
2023-10-17 09:21:40,917 - WARNING - Not Found: /favicon.ico
2023-10-18 09:45:55,816 - WARNING - Not Found: /
2023-10-18 09:45:56,027 - WARNING - Not Found: /favicon.ico
2023-10-18 09:46:17,288 - WARNING - Not Found: /
2023-10-18 09:55:53,159 - WARNING - Not Found: /path-to-javascript-file.js
2023-10-20 11:58:32,318 - WARNING - Not Found: /
2023-10-20 11:58:32,551 - WARNING - Not Found: /favicon.ico
2023-10-20 12:06:32,718 - INFO - D:\Coding\Projects\designcrafter\designcrafter\designcrafter\views.py changed, reloading.
2023-10-20 12:14:48,446 - INFO - D:\Coding\Projects\designcrafter\designcrafter\designcrafter\views.py changed, reloading.
2023-10-20 12:17:15,269 - INFO - D:\Coding\Projects\designcrafter\designcrafter\designcrafter\urls.py changed, reloading.
2023-10-20 12:30:14,775 - INFO - D:\Coding\Projects\designcrafter\designcrafter\designcrafter\views.py changed, reloading.
2023-10-20 12:30:53,758 - INFO - D:\Coding\Projects\designcrafter\designcrafter\designcrafter\urls.py changed, reloading.
2023-10-20 12:36:31,955 - WARNING - Not Found: /
2023-10-20 12:36:38,315 - ERROR - Internal Server Error: /designupload
Traceback (most recent call last):
  File "C:\python311\Lib\site-packages\django\core\handlers\exception.py", line 55, in inner
    response = get_response(request)
               ^^^^^^^^^^^^^^^^^^^^^
  File "C:\python311\Lib\site-packages\django\core\handlers\base.py", line 204, in _get_response
    self.check_response(response, callback)
  File "C:\python311\Lib\site-packages\django\core\handlers\base.py", line 332, in check_response
    raise ValueError(
ValueError: The view designcrafter.views.designupload didn't return an HttpResponse object. It returned None instead.
2023-10-20 12:36:52,499 - WARNING - Not Found: /designuploadpage
2023-10-20 12:48:42,587 - WARNING - Forbidden (CSRF token missing.): /designupload
2023-10-20 12:49:57,169 - WARNING - Forbidden (CSRF token missing.): /designupload
2023-10-20 12:58:30,873 - ERROR - Internal Server Error: /designupload
Traceback (most recent call last):
  File "C:\python311\Lib\site-packages\django\utils\datastructures.py", line 84, in __getitem__
    list_ = super().__getitem__(key)
            ^^^^^^^^^^^^^^^^^^^^^^^^
KeyError: 'file'

During handling of the above exception, another exception occurred:

Traceback (most recent call last):
  File "C:\python311\Lib\site-packages\django\core\handlers\exception.py", line 55, in inner
    response = get_response(request)
               ^^^^^^^^^^^^^^^^^^^^^
  File "C:\python311\Lib\site-packages\django\core\handlers\base.py", line 197, in _get_response
    response = wrapped_callback(request, *callback_args, **callback_kwargs)
               ^^^^^^^^^^^^^^^^^^^^^^^^^^^^^^^^^^^^^^^^^^^^^^^^^^^^^^^^^^^^
  File "D:\Coding\Projects\designcrafter\designcrafter\designcrafter\views.py", line 145, in designupload
    uploaded_file = request.FILES['file']
                    ~~~~~~~~~~~~~^^^^^^^^
  File "C:\python311\Lib\site-packages\django\utils\datastructures.py", line 86, in __getitem__
    raise MultiValueDictKeyError(key)
django.utils.datastructures.MultiValueDictKeyError: 'file'
2023-10-20 12:58:39,152 - ERROR - Internal Server Error: /designupload
Traceback (most recent call last):
  File "C:\python311\Lib\site-packages\django\core\handlers\exception.py", line 55, in inner
    response = get_response(request)
               ^^^^^^^^^^^^^^^^^^^^^
  File "C:\python311\Lib\site-packages\django\core\handlers\base.py", line 197, in _get_response
    response = wrapped_callback(request, *callback_args, **callback_kwargs)
               ^^^^^^^^^^^^^^^^^^^^^^^^^^^^^^^^^^^^^^^^^^^^^^^^^^^^^^^^^^^^
  File "D:\Coding\Projects\designcrafter\designcrafter\designcrafter\views.py", line 152, in designupload
    with open(file_path, 'wb') as destination_file:
         ^^^^^^^^^^^^^^^^^^^^^
PermissionError: [Errno 13] Permission denied: 'D:\\Coding\\Projects\\designcrafter\\designcrafter\\staticfiles\\images/newdir/2c7dd5fc-a467-46ab-ae58-a9167639f9cd.png'
2023-10-20 13:00:55,041 - INFO - D:\Coding\Projects\designcrafter\designcrafter\designcrafter\views.py changed, reloading.
2023-10-20 13:30:24,139 - INFO - D:\Coding\Projects\designcrafter\designcrafter\designcrafter\views.py changed, reloading.
2023-10-23 09:16:49,512 - WARNING - Not Found: /
2023-10-23 09:16:49,726 - WARNING - Not Found: /favicon.ico
2023-10-23 09:17:08,181 - ERROR - Internal Server Error: /designupload
Traceback (most recent call last):
  File "C:\python311\Lib\site-packages\django\core\handlers\exception.py", line 55, in inner
    response = get_response(request)
               ^^^^^^^^^^^^^^^^^^^^^
  File "C:\python311\Lib\site-packages\django\core\handlers\base.py", line 197, in _get_response
    response = wrapped_callback(request, *callback_args, **callback_kwargs)
               ^^^^^^^^^^^^^^^^^^^^^^^^^^^^^^^^^^^^^^^^^^^^^^^^^^^^^^^^^^^^
  File "D:\Coding\Projects\designcrafter\designcrafter\designcrafter\views.py", line 152, in designupload
    with open(file_path, 'wb') as destination_file:
         ^^^^^^^^^^^^^^^^^^^^^
PermissionError: [Errno 13] Permission denied: 'D:\\Coding\\Projects\\designcrafter\\designcrafter\\staticfiles\\images/designs/385dcde4-f670-4399-a8fa-b572b0a8602c.png'
